Workbook

Sheet CVHT01.Báo cáo
A1: Ngày bàn giao
A2: BC sản phẩm Kaiwa | D2: Từ ngày | E2: 45658
D3: Tới ngày | E3: =now() -> 46283.476
A4: A.Số lượng học viên
A5: Tổng | D5: =sum(D6:D10) -> 7
A6: Sắp học | D6: =COUNTIFS('1.Chăm sóc'!$B:$B,">=" &$E$2,'1.Chăm sóc'!$B:$B,"<=" &$E$3,'1.Chăm sóc'!$V:$V,A6) -> 0
A7: Chưa học | D7: =COUNTIFS('1.Chăm sóc'!$B:$B,">=" &$E$2,'1.Chăm sóc'!$B:$B,"<=" &$E$3,'1.Chăm sóc'!$V:$V,A7) -> 0
A8: Đang học | D8: =COUNTIFS('1.Chăm sóc'!$B:$B,">=" &$E$2,'1.Chăm sóc'!$B:$B,"<=" &$E$3,'1.Chăm sóc'!$V:$V,A8) -> 3
A9: Bảo lưu | D9: =COUNTIFS('1.Chăm sóc'!$B:$B,">=" &$E$2,'1.Chăm sóc'!$B:$B,"<=" &$E$3,'1.Chăm sóc'!$V:$V,A9) -> 3
A10: Kết thúc | D10: =COUNTIFS('1.Chăm sóc'!$B:$B,">=" &$E$2,'1.Chăm sóc'!$B:$B,"<=" &$E$3,'1.Chăm sóc'!$V:$V,A10) -> 1
A12: Tỷ trọng | F12: Note
A13: Sắp học | D13: =D6/$D$5 -> 0 | F13: Ưu tiên xếp lớp, làm bạn
A14: Chưa học | D14: =D7/$D$5 -> 0 | F14: Tạo nhóm
A15: Đang học | D15: =D8/$D$5 -> 0.42857143 | F15: Ưu tiên chăm sóc, tái tục
A16: Bảo lưu | D16: =D9/$D$5 -> 0.42857143 | F16: Hẹn lịch nhắc hv bắt đầu học
A17: Kết thúc | D17: =D10/$D$5 -> 0.14285714 | F17: Hỏi thăm ,kết nối 3 tháng 1 lần
A18: 46082
A19: =now() -> 46283.476
A20: B.Tình hình chăm sóc - Số HV | D20: A1 | E20: A2 | F20: A3 | G20: A4 | H20: A5 | I20: A6 | J20: A7 | K20: A8
A21: Chọn trạng thái học viên | B21: SL HV | C21: Tổng | D21: Phản hồi tích cực | E21: Cần hỗ trợ về hệ thống | F21: Phản hồi tạm,học thêm rồi báo | G21: Cần hỗ trợ về chương trình học | H21: Cần hỗ trợ về điểm yếu của chính học viên | I21: Cần hỗ trợ về giáo viên | J21: Phản hồi tiêu cực, muốn dừng | K21: Chưa phản hồi
A22: Nội dung chăm sóc sau buổi 1 | B22: =COUNTIFS('1.Chăm sóc'!$AJ:$AJ,">=1",'1.Chăm sóc'!$B:$B,">="&$A$18,'1.Chăm sóc'!$B:$B,"<="&$A$19) -> 0 | C22: =sum(D22:K22) -> 0 | D22: =COUNTIFS('1.Chăm sóc'!$AO:$AO,D$21,'1.Chăm sóc'!$B:$B,">="&$A$18,'1.Chăm sóc'!$B:$B,"<="&$A$19) -> 0 | E22: =COUNTIFS('1.Chăm sóc'!$AO:$AO,E$21,'1.Chăm sóc'!$B:$B,">="&$A$18,'1.Chăm sóc'!$B:$B,"<="&$A$19) -> 0 | F22: =COUNTIFS('1.Chăm sóc'!$AO:$AO,F$21,'1.Chăm sóc'!$B:$B,">="&$A$18,'1.Chăm sóc'!$B:$B,"<="&$A$19) -> 0 | G22: =COUNTIFS('1.Chăm sóc'!$AO:$AO,G$21,'1.Chăm sóc'!$B:$B,">="&$A$18,'1.Chăm sóc'!$B:$B,"<="&$A$19) -> 0 | H22: =COUNTIFS('1.Chăm sóc'!$AO:$AO,H$21,'1.Chăm sóc'!$B:$B,">="&$A$18,'1.Chăm sóc'!$B:$B,"<="&$A$19) -> 0 | I22: =COUNTIFS('1.Chăm sóc'!$AO:$AO,I$21,'1.Chăm sóc'!$B:$B,">="&$A$18,'1.Chăm sóc'!$B:$B,"<="&$A$19) -> 0 | J22: =COUNTIFS('1.Chăm sóc'!$AO:$AO,J$21,'1.Chăm sóc'!$B:$B,">="&$A$18,'1.Chăm sóc'!$B:$B,"<="&$A$19) -> 0 | K22: =COUNTIFS('1.Chăm sóc'!$AO:$AO,K$21,'1.Chăm sóc'!$B:$B,">="&$A$18,'1.Chăm sóc'!$B:$B,"<="&$A$19) -> 0
A23: Nội dung chăm sóc sau buổi 3 | B23: =COUNTIFS('1.Chăm sóc'!$AJ:$AJ,">=3",'1.Chăm sóc'!$B:$B,">="&$A$18,'1.Chăm sóc'!$B:$B,"<="&$A$19) -> 0 | C23: =sum(D23:K23) -> 0 | D23: =COUNTIFS('1.Chăm sóc'!$AP:$AP,D$21,'1.Chăm sóc'!$B:$B,">="&$A$18,'1.Chăm sóc'!$B:$B,"<="&$A$19) -> 0 | E23: =COUNTIFS('1.Chăm sóc'!$AP:$AP,E$21,'1.Chăm sóc'!$B:$B,">="&$A$18,'1.Chăm sóc'!$B:$B,"<="&$A$19) -> 0 | F23: =COUNTIFS('1.Chăm sóc'!$AP:$AP,F$21,'1.Chăm sóc'!$B:$B,">="&$A$18,'1.Chăm sóc'!$B:$B,"<="&$A$19) -> 0 | G23: =COUNTIFS('1.Chăm sóc'!$AP:$AP,G$21,'1.Chăm sóc'!$B:$B,">="&$A$18,'1.Chăm sóc'!$B:$B,"<="&$A$19) -> 0 | H23: =COUNTIFS('1.Chăm sóc'!$AP:$AP,H$21,'1.Chăm sóc'!$B:$B,">="&$A$18,'1.Chăm sóc'!$B:$B,"<="&$A$19) -> 0 | I23: =COUNTIFS('1.Chăm sóc'!$AP:$AP,I$21,'1.Chăm sóc'!$B:$B,">="&$A$18,'1.Chăm sóc'!$B:$B,"<="&$A$19) -> 0 | J23: =COUNTIFS('1.Chăm sóc'!$AP:$AP,J$21,'1.Chăm sóc'!$B:$B,">="&$A$18,'1.Chăm sóc'!$B:$B,"<="&$A$19) -> 0 | K23: =COUNTIFS('1.Chăm sóc'!$AP:$AP,K$21,'1.Chăm sóc'!$B:$B,">="&$A$18,'1.Chăm sóc'!$B:$B,"<="&$A$19) -> 0
A24: Nội dung chăm sóc sau buổi 10 | B24: =COUNTIFS('1.Chăm sóc'!$AJ:$AJ,">=10",'1.Chăm sóc'!$B:$B,">="&$A$18,'1.Chăm sóc'!$B:$B,"<="&$A$19) -> 0 | C24: =sum(D24:K24) -> 0 | D24: =COUNTIFS('1.Chăm sóc'!$AQ:$AQ,D$21,'1.Chăm sóc'!$B:$B,">="&$A$18,'1.Chăm sóc'!$B:$B,"<="&$A$19) -> 0 | E24: =COUNTIFS('1.Chăm sóc'!$AQ:$AQ,E$21,'1.Chăm sóc'!$B:$B,">="&$A$18,'1.Chăm sóc'!$B:$B,"<="&$A$19) -> 0 | F24: =COUNTIFS('1.Chăm sóc'!$AQ:$AQ,F$21,'1.Chăm sóc'!$B:$B,">="&$A$18,'1.Chăm sóc'!$B:$B,"<="&$A$19) -> 0 | G24: =COUNTIFS('1.Chăm sóc'!$AQ:$AQ,G$21,'1.Chăm sóc'!$B:$B,">="&$A$18,'1.Chăm sóc'!$B:$B,"<="&$A$19) -> 0 | H24: =COUNTIFS('1.Chăm sóc'!$AQ:$AQ,H$21,'1.Chăm sóc'!$B:$B,">="&$A$18,'1.Chăm sóc'!$B:$B,"<="&$A$19) -> 0 | I24: =COUNTIFS('1.Chăm sóc'!$AQ:$AQ,I$21,'1.Chăm sóc'!$B:$B,">="&$A$18,'1.Chăm sóc'!$B:$B,"<="&$A$19) -> 0 | J24: =COUNTIFS('1.Chăm sóc'!$AQ:$AQ,J$21,'1.Chăm sóc'!$B:$B,">="&$A$18,'1.Chăm sóc'!$B:$B,"<="&$A$19) -> 0 | K24: =COUNTIFS('1.Chăm sóc'!$AQ:$AQ,K$21,'1.Chăm sóc'!$B:$B,">="&$A$18,'1.Chăm sóc'!$B:$B,"<="&$A$19) -> 0
A25: Nội dung chăm sóc sau buổi 15 | B25: =COUNTIFS('1.Chăm sóc'!$AJ:$AJ,">=15",'1.Chăm sóc'!$B:$B,">="&$A$18,'1.Chăm sóc'!$B:$B,"<="&$A$19) -> 0 | C25: =sum(D25:K25) -> 0 | D25: =COUNTIFS('1.Chăm sóc'!$AR:$AR,D$21,'1.Chăm sóc'!$B:$B,">="&$A$18,'1.Chăm sóc'!$B:$B,"<="&$A$19) -> 0 | E25: =COUNTIFS('1.Chăm sóc'!$AR:$AR,E$21,'1.Chăm sóc'!$B:$B,">="&$A$18,'1.Chăm sóc'!$B:$B,"<="&$A$19) -> 0 | F25: =COUNTIFS('1.Chăm sóc'!$AR:$AR,F$21,'1.Chăm sóc'!$B:$B,">="&$A$18,'1.Chăm sóc'!$B:$B,"<="&$A$19) -> 0 | G25: =COUNTIFS('1.Chăm sóc'!$AR:$AR,G$21,'1.Chăm sóc'!$B:$B,">="&$A$18,'1.Chăm sóc'!$B:$B,"<="&$A$19) -> 0 | H25: =COUNTIFS('1.Chăm sóc'!$AR:$AR,H$21,'1.Chăm sóc'!$B:$B,">="&$A$18,'1.Chăm sóc'!$B:$B,"<="&$A$19) -> 0 | I25: =COUNTIFS('1.Chăm sóc'!$AR:$AR,I$21,'1.Chăm sóc'!$B:$B,">="&$A$18,'1.Chăm sóc'!$B:$B,"<="&$A$19) -> 0 | J25: =COUNTIFS('1.Chăm sóc'!$AR:$AR,J$21,'1.Chăm sóc'!$B:$B,">="&$A$18,'1.Chăm sóc'!$B:$B,"<="&$A$19) -> 0 | K25: =COUNTIFS('1.Chăm sóc'!$AR:$AR,K$21,'1.Chăm sóc'!$B:$B,">="&$A$18,'1.Chăm sóc'!$B:$B,"<="&$A$19) -> 0
A26: Nội dung chăm sóc sau buổi 20 | B26: =COUNTIFS('1.Chăm sóc'!$AJ:$AJ,">=20",'1.Chăm sóc'!$B:$B,">="&$A$18,'1.Chăm sóc'!$B:$B,"<="&$A$19) -> 0 | C26: =sum(D26:K26) -> 0 | D26: =COUNTIFS('1.Chăm sóc'!$AS:$AS,D$21,'1.Chăm sóc'!$B:$B,">="&$A$18,'1.Chăm sóc'!$B:$B,"<="&$A$19) -> 0 | E26: =COUNTIFS('1.Chăm sóc'!$AS:$AS,E$21,'1.Chăm sóc'!$B:$B,">="&$A$18,'1.Chăm sóc'!$B:$B,"<="&$A$19) -> 0 | F26: =COUNTIFS('1.Chăm sóc'!$AS:$AS,F$21,'1.Chăm sóc'!$B:$B,">="&$A$18,'1.Chăm sóc'!$B:$B,"<="&$A$19) -> 0 | G26: =COUNTIFS('1.Chăm sóc'!$AS:$AS,G$21,'1.Chăm sóc'!$B:$B,">="&$A$18,'1.Chăm sóc'!$B:$B,"<="&$A$19) -> 0 | H26: =COUNTIFS('1.Chăm sóc'!$AS:$AS,H$21,'1.Chăm sóc'!$B:$B,">="&$A$18,'1.Chăm sóc'!$B:$B,"<="&$A$19) -> 0 | I26: =COUNTIFS('1.Chăm sóc'!$AS:$AS,I$21,'1.Chăm sóc'!$B:$B,">="&$A$18,'1.Chăm sóc'!$B:$B,"<="&$A$19) -> 0 | J26: =COUNTIFS('1.Chăm sóc'!$AS:$AS,J$21,'1.Chăm sóc'!$B:$B,">="&$A$18,'1.Chăm sóc'!$B:$B,"<="&$A$19) -> 0 | K26: =COUNTIFS('1.Chăm sóc'!$AS:$AS,K$21,'1.Chăm sóc'!$B:$B,">="&$A$18,'1.Chăm sóc'!$B:$B,"<="&$A$19) -> 0
A27: Nội dung chăm sóc sau buổi 25 | B27: =COUNTIFS('1.Chăm sóc'!$AJ:$AJ,">=25",'1.Chăm sóc'!$B:$B,">="&$A$18,'1.Chăm sóc'!$B:$B,"<="&$A$19) -> 0 | C27: =sum(D27:K27) -> 0 | D27: =COUNTIFS('1.Chăm sóc'!$AT:$AT,D$21,'1.Chăm sóc'!$B:$B,">="&$A$18,'1.Chăm sóc'!$B:$B,"<="&$A$19) -> 0 | E27: =COUNTIFS('1.Chăm sóc'!$AT:$AT,E$21,'1.Chăm sóc'!$B:$B,">="&$A$18,'1.Chăm sóc'!$B:$B,"<="&$A$19) -> 0 | F27: =COUNTIFS('1.Chăm sóc'!$AT:$AT,F$21,'1.Chăm sóc'!$B:$B,">="&$A$18,'1.Chăm sóc'!$B:$B,"<="&$A$19) -> 0 | G27: =COUNTIFS('1.Chăm sóc'!$AT:$AT,G$21,'1.Chăm sóc'!$B:$B,">="&$A$18,'1.Chăm sóc'!$B:$B,"<="&$A$19) -> 0 | H27: =COUNTIFS('1.Chăm sóc'!$AT:$AT,H$21,'1.Chăm sóc'!$B:$B,">="&$A$18,'1.Chăm sóc'!$B:$B,"<="&$A$19) -> 0 | I27: =COUNTIFS('1.Chăm sóc'!$AT:$AT,I$21,'1.Chăm sóc'!$B:$B,">="&$A$18,'1.Chăm sóc'!$B:$B,"<="&$A$19) -> 0 | J27: =COUNTIFS('1.Chăm sóc'!$AT:$AT,J$21,'1.Chăm sóc'!$B:$B,">="&$A$18,'1.Chăm sóc'!$B:$B,"<="&$A$19) -> 0 | K27: =COUNTIFS('1.Chăm sóc'!$AT:$AT,K$21,'1.Chăm sóc'!$B:$B,">="&$A$18,'1.Chăm sóc'!$B:$B,"<="&$A$19) -> 0
A28: Nội dung chăm sóc sau buổi 29 | B28: =COUNTIFS('1.Chăm sóc'!$AJ:$AJ,">=29",'1.Chăm sóc'!$B:$B,">="&$A$18,'1.Chăm sóc'!$B:$B,"<="&$A$19) -> 0 | C28: =sum(D28:K28) -> 0 | D28: =COUNTIFS('1.Chăm sóc'!$AU:$AU,D$21,'1.Chăm sóc'!$B:$B,">="&$A$18,'1.Chăm sóc'!$B:$B,"<="&$A$19) -> 0 | E28: =COUNTIFS('1.Chăm sóc'!$AU:$AU,E$21,'1.Chăm sóc'!$B:$B,">="&$A$18,'1.Chăm sóc'!$B:$B,"<="&$A$19) -> 0 | F28: =COUNTIFS('1.Chăm sóc'!$AU:$AU,F$21,'1.Chăm sóc'!$B:$B,">="&$A$18,'1.Chăm sóc'!$B:$B,"<="&$A$19) -> 0 | G28: =COUNTIFS('1.Chăm sóc'!$AU:$AU,G$21,'1.Chăm sóc'!$B:$B,">="&$A$18,'1.Chăm sóc'!$B:$B,"<="&$A$19) -> 0 | H28: =COUNTIFS('1.Chăm sóc'!$AU:$AU,H$21,'1.Chăm sóc'!$B:$B,">="&$A$18,'1.Chăm sóc'!$B:$B,"<="&$A$19) -> 0 | I28: =COUNTIFS('1.Chăm sóc'!$AU:$AU,I$21,'1.Chăm sóc'!$B:$B,">="&$A$18,'1.Chăm sóc'!$B:$B,"<="&$A$19) -> 0 | J28: =COUNTIFS('1.Chăm sóc'!$AU:$AU,J$21,'1.Chăm sóc'!$B:$B,">="&$A$18,'1.Chăm sóc'!$B:$B,"<="&$A$19) -> 0 | K28: =COUNTIFS('1.Chăm sóc'!$AU:$AU,K$21,'1.Chăm sóc'!$B:$B,">="&$A$18,'1.Chăm sóc'!$B:$B,"<="&$A$19) -> 0
A29: Nội dung chăm sóc sau buổi 30 | B29: =COUNTIFS('1.Chăm sóc'!$AJ:$AJ,">=30",'1.Chăm sóc'!$B:$B,">="&$A$18,'1.Chăm sóc'!$B:$B,"<="&$A$19) -> 0 | C29: =sum(D29:K29) -> 0 | D29: =COUNTIFS('1.Chăm sóc'!$AV:$AV,D$21,'1.Chăm sóc'!$B:$B,">="&$A$18,'1.Chăm sóc'!$B:$B,"<="&$A$19) -> 0 | E29: =COUNTIFS('1.Chăm sóc'!$AV:$AV,E$21,'1.Chăm sóc'!$B:$B,">="&$A$18,'1.Chăm sóc'!$B:$B,"<="&$A$19) -> 0 | F29: =COUNTIFS('1.Chăm sóc'!$AV:$AV,F$21,'1.Chăm sóc'!$B:$B,">="&$A$18,'1.Chăm sóc'!$B:$B,"<="&$A$19) -> 0 | G29: =COUNTIFS('1.Chăm sóc'!$AV:$AV,G$21,'1.Chăm sóc'!$B:$B,">="&$A$18,'1.Chăm sóc'!$B:$B,"<="&$A$19) -> 0 | H29: =COUNTIFS('1.Chăm sóc'!$AV:$AV,H$21,'1.Chăm sóc'!$B:$B,">="&$A$18,'1.Chăm sóc'!$B:$B,"<="&$A$19) -> 0 | I29: =COUNTIFS('1.Chăm sóc'!$AV:$AV,I$21,'1.Chăm sóc'!$B:$B,">="&$A$18,'1.Chăm sóc'!$B:$B,"<="&$A$19) -> 0 | J29: =COUNTIFS('1.Chăm sóc'!$AV:$AV,J$21,'1.Chăm sóc'!$B:$B,">="&$A$18,'1.Chăm sóc'!$B:$B,"<="&$A$19) -> 0 | K29: =COUNTIFS('1.Chăm sóc'!$AV:$AV,K$21,'1.Chăm sóc'!$B:$B,">="&$A$18,'1.Chăm sóc'!$B:$B,"<="&$A$19) -> 0
A30: Nội dung chăm sóc sau buổi 35 | B30: =COUNTIFS('1.Chăm sóc'!$AJ:$AJ,">=35",'1.Chăm sóc'!$B:$B,">="&$A$18,'1.Chăm sóc'!$B:$B,"<="&$A$19) -> 0 | C30: =sum(D30:K30) -> 0 | D30: =COUNTIFS('1.Chăm sóc'!$AW:$AW,D$21,'1.Chăm sóc'!$B:$B,">="&$A$18,'1.Chăm sóc'!$B:$B,"<="&$A$19) -> 0 | E30: =COUNTIFS('1.Chăm sóc'!$AW:$AW,E$21,'1.Chăm sóc'!$B:$B,">="&$A$18,'1.Chăm sóc'!$B:$B,"<="&$A$19) -> 0 | F30: =COUNTIFS('1.Chăm sóc'!$AW:$AW,F$21,'1.Chăm sóc'!$B:$B,">="&$A$18,'1.Chăm sóc'!$B:$B,"<="&$A$19) -> 0 | G30: =COUNTIFS('1.Chăm sóc'!$AW:$AW,G$21,'1.Chăm sóc'!$B:$B,">="&$A$18,'1.Chăm sóc'!$B:$B,"<="&$A$19) -> 0 | H30: =COUNTIFS('1.Chăm sóc'!$AW:$AW,H$21,'1.Chăm sóc'!$B:$B,">="&$A$18,'1.Chăm sóc'!$B:$B,"<="&$A$19) -> 0 | I30: =COUNTIFS('1.Chăm sóc'!$AW:$AW,I$21,'1.Chăm sóc'!$B:$B,">="&$A$18,'1.Chăm sóc'!$B:$B,"<="&$A$19) -> 0 | J30: =COUNTIFS('1.Chăm sóc'!$AW:$AW,J$21,'1.Chăm sóc'!$B:$B,">="&$A$18,'1.Chăm sóc'!$B:$B,"<="&$A$19) -> 0 | K30: =COUNTIFS('1.Chăm sóc'!$AW:$AW,K$21,'1.Chăm sóc'!$B:$B,">="&$A$18,'1.Chăm sóc'!$B:$B,"<="&$A$19) -> 0
A31: Nội dung chăm sóc sau buổi 45 | B31: =COUNTIFS('1.Chăm sóc'!$AJ:$AJ,">=45",'1.Chăm sóc'!$B:$B,">="&$A$18,'1.Chăm sóc'!$B:$B,"<="&$A$19) -> 0 | C31: =sum(D31:K31) -> 0 | D31: =COUNTIFS('1.Chăm sóc'!$AX:$AX,D$21,'1.Chăm sóc'!$B:$B,">="&$A$18,'1.Chăm sóc'!$B:$B,"<="&$A$19) -> 0 | E31: =COUNTIFS('1.Chăm sóc'!$AX:$AX,E$21,'1.Chăm sóc'!$B:$B,">="&$A$18,'1.Chăm sóc'!$B:$B,"<="&$A$19) -> 0 | F31: =COUNTIFS('1.Chăm sóc'!$AX:$AX,F$21,'1.Chăm sóc'!$B:$B,">="&$A$18,'1.Chăm sóc'!$B:$B,"<="&$A$19) -> 0 | G31: =COUNTIFS('1.Chăm sóc'!$AX:$AX,G$21,'1.Chăm sóc'!$B:$B,">="&$A$18,'1.Chăm sóc'!$B:$B,"<="&$A$19) -> 0 | H31: =COUNTIFS('1.Chăm sóc'!$AX:$AX,H$21,'1.Chăm sóc'!$B:$B,">="&$A$18,'1.Chăm sóc'!$B:$B,"<="&$A$19) -> 0 | I31: =COUNTIFS('1.Chăm sóc'!$AX:$AX,I$21,'1.Chăm sóc'!$B:$B,">="&$A$18,'1.Chăm sóc'!$B:$B,"<="&$A$19) -> 0 | J31: =COUNTIFS('1.Chăm sóc'!$AX:$AX,J$21,'1.Chăm sóc'!$B:$B,">="&$A$18,'1.Chăm sóc'!$B:$B,"<="&$A$19) -> 0 | K31: =COUNTIFS('1.Chăm sóc'!$AX:$AX,K$21,'1.Chăm sóc'!$B:$B,">="&$A$18,'1.Chăm sóc'!$B:$B,"<="&$A$19) -> 0
A32: Nội dung chăm sóc sau buổi 55 | B32: =COUNTIFS('1.Chăm sóc'!$AJ:$AJ,">=55",'1.Chăm sóc'!$B:$B,">="&$A$18,'1.Chăm sóc'!$B:$B,"<="&$A$19) -> 0 | C32: =sum(D32:K32) -> 0 | D32: =COUNTIFS('1.Chăm sóc'!$AY:$AY,D$21,'1.Chăm sóc'!$B:$B,">="&$A$18,'1.Chăm sóc'!$B:$B,"<="&$A$19) -> 0 | E32: =COUNTIFS('1.Chăm sóc'!$AY:$AY,E$21,'1.Chăm sóc'!$B:$B,">="&$A$18,'1.Chăm sóc'!$B:$B,"<="&$A$19) -> 0 | F32: =COUNTIFS('1.Chăm sóc'!$AY:$AY,F$21,'1.Chăm sóc'!$B:$B,">="&$A$18,'1.Chăm sóc'!$B:$B,"<="&$A$19) -> 0 | G32: =COUNTIFS('1.Chăm sóc'!$AY:$AY,G$21,'1.Chăm sóc'!$B:$B,">="&$A$18,'1.Chăm sóc'!$B:$B,"<="&$A$19) -> 0 | H32: =COUNTIFS('1.Chăm sóc'!$AY:$AY,H$21,'1.Chăm sóc'!$B:$B,">="&$A$18,'1.Chăm sóc'!$B:$B,"<="&$A$19) -> 0 | I32: =COUNTIFS('1.Chăm sóc'!$AY:$AY,I$21,'1.Chăm sóc'!$B:$B,">="&$A$18,'1.Chăm sóc'!$B:$B,"<="&$A$19) -> 0 | J32: =COUNTIFS('1.Chăm sóc'!$AY:$AY,J$21,'1.Chăm sóc'!$B:$B,">="&$A$18,'1.Chăm sóc'!$B:$B,"<="&$A$19) -> 0 | K32: =COUNTIFS('1.Chăm sóc'!$AY:$AY,K$21,'1.Chăm sóc'!$B:$B,">="&$A$18,'1.Chăm sóc'!$B:$B,"<="&$A$19) -> 0
A33: Nội dung chăm sóc sau buổi 59 | B33: =COUNTIFS('1.Chăm sóc'!$AJ:$AJ,">=59",'1.Chăm sóc'!$B:$B,">="&$A$18,'1.Chăm sóc'!$B:$B,"<="&$A$19) -> 0 | C33: =sum(D33:K33) -> 0 | D33: =COUNTIFS('1.Chăm sóc'!$AZ:$AZ,D$21,'1.Chăm sóc'!$B:$B,">="&$A$18,'1.Chăm sóc'!$B:$B,"<="&$A$19) -> 0 | E33: =COUNTIFS('1.Chăm sóc'!$AZ:$AZ,E$21,'1.Chăm sóc'!$B:$B,">="&$A$18,'1.Chăm sóc'!$B:$B,"<="&$A$19) -> 0 | F33: =COUNTIFS('1.Chăm sóc'!$AZ:$AZ,F$21,'1.Chăm sóc'!$B:$B,">="&$A$18,'1.Chăm sóc'!$B:$B,"<="&$A$19) -> 0 | G33: =COUNTIFS('1.Chăm sóc'!$AZ:$AZ,G$21,'1.Chăm sóc'!$B:$B,">="&$A$18,'1.Chăm sóc'!$B:$B,"<="&$A$19) -> 0 | H33: =COUNTIFS('1.Chăm sóc'!$AZ:$AZ,H$21,'1.Chăm sóc'!$B:$B,">="&$A$18,'1.Chăm sóc'!$B:$B,"<="&$A$19) -> 0 | I33: =COUNTIFS('1.Chăm sóc'!$AZ:$AZ,I$21,'1.Chăm sóc'!$B:$B,">="&$A$18,'1.Chăm sóc'!$B:$B,"<="&$A$19) -> 0 | J33: =COUNTIFS('1.Chăm sóc'!$AZ:$AZ,J$21,'1.Chăm sóc'!$B:$B,">="&$A$18,'1.Chăm sóc'!$B:$B,"<="&$A$19) -> 0 | K33: =COUNTIFS('1.Chăm sóc'!$AZ:$AZ,K$21,'1.Chăm sóc'!$B:$B,">="&$A$18,'1.Chăm sóc'!$B:$B,"<="&$A$19) -> 0
A34: Nội dung chăm sóc sau buổi 60 | B34: =COUNTIFS('1.Chăm sóc'!$AJ:$AJ,">=60",'1.Chăm sóc'!$B:$B,">="&$A$18,'1.Chăm sóc'!$B:$B,"<="&$A$19) -> 0 | C34: =sum(D34:K34) -> 0 | D34: =COUNTIFS('1.Chăm sóc'!$BA:$BA,D$21,'1.Chăm sóc'!$B:$B,">="&$A$18,'1.Chăm sóc'!$B:$B,"<="&$A$19) -> 0 | E34: =COUNTIFS('1.Chăm sóc'!$BA:$BA,E$21,'1.Chăm sóc'!$B:$B,">="&$A$18,'1.Chăm sóc'!$B:$B,"<="&$A$19) -> 0 | F34: =COUNTIFS('1.Chăm sóc'!$BA:$BA,F$21,'1.Chăm sóc'!$B:$B,">="&$A$18,'1.Chăm sóc'!$B:$B,"<="&$A$19) -> 0 | G34: =COUNTIFS('1.Chăm sóc'!$BA:$BA,G$21,'1.Chăm sóc'!$B:$B,">="&$A$18,'1.Chăm sóc'!$B:$B,"<="&$A$19) -> 0 | H34: =COUNTIFS('1.Chăm sóc'!$BA:$BA,H$21,'1.Chăm sóc'!$B:$B,">="&$A$18,'1.Chăm sóc'!$B:$B,"<="&$A$19) -> 0 | I34: =COUNTIFS('1.Chăm sóc'!$BA:$BA,I$21,'1.Chăm sóc'!$B:$B,">="&$A$18,'1.Chăm sóc'!$B:$B,"<="&$A$19) -> 0 | J34: =COUNTIFS('1.Chăm sóc'!$BA:$BA,J$21,'1.Chăm sóc'!$B:$B,">="&$A$18,'1.Chăm sóc'!$B:$B,"<="&$A$19) -> 0 | K34: =COUNTIFS('1.Chăm sóc'!$BA:$BA,K$21,'1.Chăm sóc'!$B:$B,">="&$A$18,'1.Chăm sóc'!$B:$B,"<="&$A$19) -> 0
A35: Nội dung chăm sóc sau buổi 89 | B35: =COUNTIFS('1.Chăm sóc'!$AJ:$AJ,">=89",'1.Chăm sóc'!$B:$B,">="&$A$18,'1.Chăm sóc'!$B:$B,"<="&$A$19) -> 0 | C35: =sum(D35:K35) -> 0 | D35: =COUNTIFS('1.Chăm sóc'!$BB:$BB,D$21,'1.Chăm sóc'!$B:$B,">="&$A$18,'1.Chăm sóc'!$B:$B,"<="&$A$19) -> 0 | E35: =COUNTIFS('1.Chăm sóc'!$BB:$BB,E$21,'1.Chăm sóc'!$B:$B,">="&$A$18,'1.Chăm sóc'!$B:$B,"<="&$A$19) -> 0 | F35: =COUNTIFS('1.Chăm sóc'!$BB:$BB,F$21,'1.Chăm sóc'!$B:$B,">="&$A$18,'1.Chăm sóc'!$B:$B,"<="&$A$19) -> 0 | G35: =COUNTIFS('1.Chăm sóc'!$BB:$BB,G$21,'1.Chăm sóc'!$B:$B,">="&$A$18,'1.Chăm sóc'!$B:$B,"<="&$A$19) -> 0 | H35: =COUNTIFS('1.Chăm sóc'!$BB:$BB,H$21,'1.Chăm sóc'!$B:$B,">="&$A$18,'1.Chăm sóc'!$B:$B,"<="&$A$19) -> 0 | I35: =COUNTIFS('1.Chăm sóc'!$BB:$BB,I$21,'1.Chăm sóc'!$B:$B,">="&$A$18,'1.Chăm sóc'!$B:$B,"<="&$A$19) -> 0 | J35: =COUNTIFS('1.Chăm sóc'!$BB:$BB,J$21,'1.Chăm sóc'!$B:$B,">="&$A$18,'1.Chăm sóc'!$B:$B,"<="&$A$19) -> 0 | K35: =COUNTIFS('1.Chăm sóc'!$BB:$BB,K$21,'1.Chăm sóc'!$B:$B,">="&$A$18,'1.Chăm sóc'!$B:$B,"<="&$A$19) -> 0
A36: Nội dung chăm sóc sau buổi 90 | B36: =COUNTIFS('1.Chăm sóc'!$AJ:$AJ,">=90",'1.Chăm sóc'!$B:$B,">="&$A$18,'1.Chăm sóc'!$B:$B,"<="&$A$19) -> 0 | C36: =sum(D36:K36) -> 0 | D36: =COUNTIFS('1.Chăm sóc'!$BC:$BC,D$21,'1.Chăm sóc'!$B:$B,">="&$A$18,'1.Chăm sóc'!$B:$B,"<="&$A$19) -> 0 | E36: =COUNTIFS('1.Chăm sóc'!$BC:$BC,E$21,'1.Chăm sóc'!$B:$B,">="&$A$18,'1.Chăm sóc'!$B:$B,"<="&$A$19) -> 0 | F36: =COUNTIFS('1.Chăm sóc'!$BC:$BC,F$21,'1.Chăm sóc'!$B:$B,">="&$A$18,'1.Chăm sóc'!$B:$B,"<="&$A$19) -> 0 | G36: =COUNTIFS('1.Chăm sóc'!$BC:$BC,G$21,'1.Chăm sóc'!$B:$B,">="&$A$18,'1.Chăm sóc'!$B:$B,"<="&$A$19) -> 0 | H36: =COUNTIFS('1.Chăm sóc'!$BC:$BC,H$21,'1.Chăm sóc'!$B:$B,">="&$A$18,'1.Chăm sóc'!$B:$B,"<="&$A$19) -> 0 | I36: =COUNTIFS('1.Chăm sóc'!$BC:$BC,I$21,'1.Chăm sóc'!$B:$B,">="&$A$18,'1.Chăm sóc'!$B:$B,"<="&$A$19) -> 0 | J36: =COUNTIFS('1.Chăm sóc'!$BC:$BC,J$21,'1.Chăm sóc'!$B:$B,">="&$A$18,'1.Chăm sóc'!$B:$B,"<="&$A$19) -> 0 | K36: =COUNTIFS('1.Chăm sóc'!$BC:$BC,K$21,'1.Chăm sóc'!$B:$B,">="&$A$18,'1.Chăm sóc'!$B:$B,"<="&$A$19) -> 0
A38: B.Tình hình chăm sóc - Tỷ lệ | D38: A1 | E38: A2 | F38: A3 | G38: A4 | H38: A5 | I38: A6 | J38: A7 | K38: A8
A39: Chọn trạng thái học viên | B39: SL HV | C39: Tổng | D39: Phản hồi tích cực | E39: Cần hỗ trợ về hệ thống | F39: Phản hồi tạm,học thêm rồi báo | G39: Cần hỗ trợ về chương trình học | H39: Cần hỗ trợ về điểm yếu của chính học viên | I39: Cần hỗ trợ về giáo viên | J39: Phản hồi tiêu cực, muốn dừng | K39: Chưa phản hồi
A40: Nội dung chăm sóc sau buổi 1 | D40: =iferror(D$22/$C22,0) -> 0 | E40: =iferror(E$22/$C22,0) -> 0 | F40: =iferror(F$22/$C22,0) -> 0 | G40: =iferror(G$22/$C22,0) -> 0 | H40: =iferror(H$22/$C22,0) -> 0 | I40: =iferror(I$22/$C22,0) -> 0 | J40: =iferror(J$22/$C22,0) -> 0 | K40: =iferror(K$22/$C22,0) -> 0
A41: Nội dung chăm sóc sau buổi 3 | D41: =iferror(D23/$C23,0) -> 0 | E41: =iferror(E23/$C23,0) -> 0 | F41: =iferror(F23/$C23,0) -> 0 | G41: =iferror(G23/$C23,0) -> 0 | H41: =iferror(H23/$C23,0) -> 0 | I41: =iferror(I23/$C23,0) -> 0 | J41: =iferror(J23/$C23,0) -> 0 | K41: =iferror(K23/$C23,0) -> 0
A42: Nội dung chăm sóc sau buổi 10 | D42: =iferror(D24/$C24,0) -> 0 | E42: =iferror(E24/$C24,0) -> 0 | F42: =iferror(F24/$C24,0) -> 0 | G42: =iferror(G24/$C24,0) -> 0 | H42: =iferror(H24/$C24,0) -> 0 | I42: =iferror(I24/$C24,0) -> 0 | J42: =iferror(J24/$C24,0) -> 0 | K42: =iferror(K24/$C24,0) -> 0
...

Sheet 1.Chăm sóc
B1: 2 | C1: 3 | D1: 4 | E1: 5 | F1: 6 | G1: 7 | H1: 8 | I1: 9 | J1: 10 | K1: 11 | L1: 12 | M1: 13 | N1: 14 | O1: 15 | P1: 16 | Q1: 17 | R1: 18 | S1: 19 | T1: ff | U1: 21 | V1: 22 | W1: 23 | X1: 24 | Y1: 25 | Z1: 26 | AA1: 27 | AB1: 28 | AC1: 29 | AD1: 30 | AE1: 31 | AF1: 32 | AG1: 33 | AH1: 34 | AI1: 35 | AJ1: 36 | AK1: 37 | AL1: 38 | AM1: 39 | AN1: 40 | AO1: 41 | AP1: 42 | AQ1: 43 | AR1: 44 | AS1: 45 | AT1: 46 | AU1: 47 | AV1: 48 | AW1: 49 | AX1: 50 | AY1: 51 | AZ1: 52 | BA1: 53 | BB1: 54 | BC1: 55 | BD1: 56 | BE1: 57 | BF1: 58 | BG1: 59 | BH1: 60
A2: THÔNG TIN KHOÁ HỌC
A3: ID | B3: Ngày nộp học phí | C3: Sale | D3: Trạng thái HV | E3: Họ tên HV | F3: Giới tính | G3: SĐT | H3: Email | I3: Nội dung khoá | J3: Trạng thái thanh toán | K3: Gói học | L3: Khoá học | M3: Trình độ | N3: Tổng số buổi | O3: Mô hình lớp | P3: Ghi chú sale | Q3: DOB | R3: Nghề nghiệp | S3: Mô hình | T3: Số buổi còn lại | U3: Ngày bắt đầu học | V3: Trạng thái | W3: Ngày kết thúc/Bảo lưu | X3: Giờ học (1) | Y3: Lịch học (1) | Z3: Thời lượng buổi học (1) | AA3: Giờ học (2) | AB3: Lịch học (2) | AC3: Thời lượng buổi học (2) | AD3: Vòng lặp | AE3: Ngày học | AF3: Giáo viên | AG3: Mã GV | AH3: Tên lớp | AI3: Tổng số buổi đã học năm trước | AJ3: Tổng số buổi đã học 2026 | AK3: Báo cáo học tập | AL3: Thông tin trao đổi với HV | AM3: Lịch hẹn gọi | AN3: Điểm nóng | AO3: Nội dung chăm sóc sau buổi 1 | AP3: Nội dung chăm sóc sau buổi 3 | AQ3: Nội dung chăm sóc sau buổi 10 | AR3: Nội dung chăm sóc sau buổi 15 | AS3: Nội dung chăm sóc sau buổi 20 | AT3: Nội dung chăm sóc sau buổi 25 | AU3: Nội dung chăm sóc sau buổi 29 | AV3: Nội dung chăm sóc sau buổi 30 | AW3: Nội dung chăm sóc sau buổi 35 | AX3: Nội dung chăm sóc sau buổi 45 | AY3: Nội dung chăm sóc sau buổi 55 | AZ3: Nội dung chăm sóc sau buổi 59 | BA3: Nội dung chăm sóc sau buổi 60 | BB3: Nội dung chăm sóc sau buổi 89 | BC3: Nội dung chăm sóc sau buổi 90 | BD3: Chăm sóc sau kết thúc | BE3: =W3 -> Ngày kết thúc/Bảo lưu | BF3: Ngày bàn giao | BG3: Tháng nộp học phí | BH3: Ngày tạo tài khoản
A4: 420274574 | B4: 45673.58 | C4: DuyenLT | D4: HV mới | E4: Đặng Văn Thạch | F4: Nữ | G4: 7012519244 | H4: thachcd111cg2@gmail.com | I4: Thường | J4: Full phí | K4: SKAI231030VN | L4: GV Việt Nam | M4: Kaiwa 2 | N4: 49 | O4: Lớp 1-1 | P4: - Liên hệ zalo: 7012519244 - tặng video jlptN3 - Lịch học: 246, giờ 21-21h30 (giờ nhật) - sn 91, cả gia đình qua nhật, muốn học để làm giấy tờ cho con. | Q4: 33513 | R4: công nghiệp chế tạo | S4: Lớp 1-1 | T4: 14 | U4: 45698 | V4: Đang học | W4: 45736 | X4: 20h00 | Y4: 246 | Z4: 30 | AF4: kojima/thaodtt | AG4: GV33 | AH4: Đặng Văn Thạch - kaiwa 2 ( 22/01/2025) - 001 | AK4: Đặng Văn Thạch | AL4: - sn 91, cả gia đình qua nhật, muốn học để làm giấy tờ cho con. | AO4: 11/02/2025 E cảm nhận ss dạy hơi nhanh Và đây là lớp học luyện kaiwa nên tập trung luyện nói | AP4: 20/02/2025 E cũng quen với phương pháp dạy của Trung tâm rồi ạ | BF4: =datevalue(B4) -> 45673 | BG4: =MONTH(B4) -> 1 | BH4: 45670
A5: 420266164 | B5: 45355.429 | C5: ThuNH | D5: HV mới | E5: Phan Ngọc Khánh Linh | F5: Nữ | G5: 399669820 | H5: 10.phanngockhanhlinh11a2@gmail.com | I5: Thường | J5: Full phí | K5: SKAI11030VN | L5: GV Việt Nam | M5: Kaiwa 1 | N5: 90 | O5: Lớp 1-1 | P5: Phan Ngọc Khánh Linh 04/04/2005 0399669820 10.phanngockhanhlinh11a2@gmail.com khóa học kaiwa 1 Lịch học, thứ 246, học buổi tối ( tháng 4 qua Nhật, mong muốn khai giảng sớm) ưu đãi tặng khóa luyện thi JLPT N3 dưới dạng video bài giảng thời hạn 12 tháng | Q5: 38446 | R5: tháng 4 bay sang Nhật xklđ | S5: Lớp 1-1 | T5: 7 | U5: 45364 | V5: Đang học | W5: 45803 | X5: 9h00 | Y5: 7 | Z5: 60 | AF5: canhnt/chiaki,arita, maivt | AG5: GV426 | AH5: Phan Ngọc Khánh Linh - Kaiwa 1 (11/03/2024) - 001 Phan Ngọc Khánh Linh - Kaiwa 2 (07/08/2024) - 001 Phan Ngọc Khánh Linh - kaiwa 3 ( 05/04/2025) - 001 | AJ5: 56 | AK5: Phan Ngọc Khánh Linh | AQ5: 11/09/2024Dạ e thấy hợp vs e hơn í ạ | AZ5: 45796 | BF5: =datevalue(B5) -> 45355 | BG5: =MONTH(B5) -> 3
A6: 10052874 | B6: 45723.548 | C6: DuyenLT | D6: HV mới | E6: Phạm Thị Thương | F6: Nữ | G6: 976691294 | H6: phamthithuongnb93@gmail.com | I6: Thường | J6: Full phí | K6: CKAI121030VN | L6: GV Việt Nam | M6: Kaiwa 1 | N6: 60 | O6: Lớp 1-1 | P6: - Liên hệ zalo: 976691294 - tặng jlpt N5,N4 - Lịch học: 246, giờ: chưa chốt - HV sn 93, sợ học chậm, muốn ss nữ, nhiệt tình, vui tính hỗ trợ. Muốn học sớm để hỗ trợ luyện pv 1-2 hôm. (đã trao đổi là luyện sẽ tính vào buổi học) | Q6: 34114 | R6: tts nông nghiệp | S6: Lớp 1-1 | T6: 20 | U6: 45735 | V6: Đang học | W6: 45859 | X6: 20h00 | Y6: 246 | Z6: 30 | AF6: quyentn/diempvk | AG6: GV396 | AH6: Phạm Thị Thương - kaiwa 1 ( 12/03/2025 ) - 001 Phạm Thị Thương - kaiwa 2 ( 10/12/2025 ) - 001 | AK6: Phạm Thị Thương | AL6: - Mục tiêu học: muốn học kaiwa phục vụ công việc | AO6: 20/03/2025 Diễm ss rất nhiệt tình ah | AP6: 26/03/2025Học 30p trôi nhah lắm ss | BF6: =datevalue(B6) -> 45723 | BG6: =MONTH(B6) -> 3
A7: 420277244 | B7: 45732.43 | C7: LienQTM | D7: HV mới | E7: Trần Tế Hanh | F7: Nam | G7: 901629888 | H7: has2107@gmail.com | I7: Thường | J7: Full phí | K7: CKAI231030VN | L7: GV Việt Nam | M7: Kaiwa 2 | N7: 105 | O7: Lớp 1-1 | P7: - Zalo: 901629888 - Lớp combokaiwa 23 , lớp 1:1, giáo viên Việt(15b k3 Gv Nhật), Gv nam ,60% - Lịch học : thứ 2-4-6 , thời gian 17h Nhật - Họ và tên, năm sinh: Trần Tế Hanh, 1985 - Email: has2107@gmail.com - Tăng JLPT video N4 - Mục tiêu học: học để kaiwa với sếp Nhật và đồng | Q7: 31122 | R7: đang làm công ty Nhật ở VN | S7: Lớp 1-1 | T7: 8 | U7: 45740 | V7: Đang học | X7: 17h10 | Y7: 246 | Z7: 30 | AF7: huylt | AG7: GV265 | AH7: Trần Tế Hanh - kaiwa 2 ( 21/03/2025) - 001 Trần Tế Hanh - kaiwa 3 ( 15/09/2025 ) - 001 | AK7: Trần Tế Hanh | AL7: - Mục tiêu học: học để kaiwa với sếp Nhật và đồng | AO7: 20/03/2025Buổi đầu như vậy là tốt ss ạ | AP7: 01/04/2025Dạ cũng quen hơn rồi SS | AQ7: 21/05/2025 Thầy Huy dạy rất thú vị, khóa sau anh vẫn muốn học tiếp với thầy | AV7: 28/10/2025 Huy ss dạy thú vị lắm ạ, nhiều kiến thức mở rộng hơn giáo trình ạ Nhiều ss ạ, hàng ngày tiếp xúc với người Nhật nên cũng được các bạn chỉ thêm cho tự nhiên hơn ạ | AX7: 11/12/2025 đợi ph | BF7: =datevalue(B7) -> 45732 | BG7: =MONTH(B7) -> 3
A8: 420270374 | B8: 45482.454 | C8: ThuNH | D8: HV mới | E8: Nguyễn Văn Trọng | F8: Nam | G8: 123 | H8: ba.trong.photo@gmail.com | I8: Thường | J8: Full phí | K8: SKAI31030VN | L8: GV Việt Nam | M8: Kaiwa 3 | N8: 93.293769 | O8: Lớp 1-1 | P8: LH line: https://drive.google.com/file/d/12e5-peziVXLqz2QZGOVot2NK1FInf1S_/view?usp=drive_link Họ tên: Nguyễn Văn Trọng Ngày sinh: 5/7/1999 Email: ba.trong.photo@gmail.com khóa học kaiwa 3 gv Việt lịch học học được sau 20h Nhật thứ 246 ưu đãi tặng khóa luyện thi JLPT N2 | Q8: 36346 | R8: văn phòng | S8: Lớp 1-1 | T8: 29.293769 | U8: 2024-12-12 2024-07-17 | V8: Bảo lưu | W8: 2024-11-09 2025-10-04 | X8: 18h30/19h00 | Y8: 7/246 | Z8: 30 | AF8: matsuo/ hienntt | AH8: Nguyễn Văn Trọng - kaiwa 4 ( 12/12/2024) - 001 Nguyễn Văn Trọng - Kaiwa 3 (17/07/2024) - 001 Nguyễn Văn Trọng - kaiwa 5 ( 05/07/2025 ) - 001 | AJ8: 34 | AK8: Nguyễn Văn Trọng | AS8: 16/09/2024: BTVN : 5/5 nhắc nhở | AY8: 17/05/2025 10:43 Nguyen Van Trong Dạ vâng ah, cũng có áp dụng vào cuộc sống 10:43 Nguyen Van Trong Và duy trì được tiếng Nhật ah | BF8: =datevalue(B8) -> 45482 | BG8: =MONTH(B8) -> 7 | BH8: 45482
A9: 420272465 | B9: 45572.397 | C9: LienQTM | D9: HV mới | E9: Nguyễn Duy Đắc | F9: Nam | G9: 123 | H9: duydac94@gmail.com | I9: Thường | J9: Full phí | K9: CKAI341030JP | L9: GV Nhật Bản | M9: Kaiwa 3 | N9: 150 | O9: Lớp 1-1 | P9: - Line: 080 8190 0816 - Lớp kaiwa 3+4, giáo viên Nhật: Thầy Matsto - Lịch học : thứ 2-4-6, thời gian 21h Nhật - Nguyễn Duy Đắc , 08/09/1994 - Email: duydac94@gmail.com - Tăng JLPT video N2 - Mục tiêu học: kĩ sư sang Nhật 3 năm, giờ sống với vợ và con nhỏ, muốn học kaiwa để nói chuyện được lưu loát hơn, để chuyển việc có mức lương cao hơn vì phải nuôi vợ con | Q9: 34585 | R9: kĩ sư | S9: Lớp 1-1 | T9: 26 | U9: 2024-10-11 2025-07-14 | V9: Bảo lưu | W9: 45810 | X9: 18h00 | Y9: 246 | Z9: 30 | AF9: matsuo | AH9: Nguyễn Duy Đắc - kaiwa 3 ( 11/10/2024) - 001 Nguyễn Duy Đắc - kaiwa 4 ( 13/01/2025) - 001 Nguyễn Duy Đắc - kaiwa 5 ( 10/04/2025 ) - 001 | AJ9: 28 | AK9: Nguyễn Duy Đắc | AL9: kĩ sư sang Nhật 3 năm, giờ sống với vợ và con nhỏ, muốn học kaiwa để nói | AO9: 14/10/2024 Dạ Hiện tại đang bình thường ạ. Mấy hôm nay em bận nên chưa kịp trả lời cô ạ. BTVN: 1/30 | AP9: 19/10/2024 BTVN: 2/30Dạ em quen rồi ạ. | AQ9: 05/11/2024Em vẫn đang học bình thường ạ. | AS9: 13/12/2024Dạ. Em có vận dụng được ạ. Nhưng cần thêm thời gian để nhuần nhuyễn hơn Cô ạ. | AV9: 11/02/2025Mấy hôm nay em hơi bận Em có đọc tin nhắn rồi mà em chưa kịp trả lời ạ. Phần 4 khó hơn ạ. Kiến thức cũng nhiều hơn ạ. Nhưng em nghĩ là em học được ạ. | AW9: 17/03/2025Em áp dụng được vào đời sống rồi ạ. Tiếp tục luyện tập là ổn Cô ạ. | AX9: 22/03/2025Dạ không có vấn đề gì ạ. | AY9: 24/03/2025 Em tính đăng kí nốt Kaiwa 5,6 luôn ạ | AZ9: nhắc nhở ôn tập để test | BA9: 09/04/2025 Dạ, không sao ạ. Em cảm ơn ạ. | BB9: Dạ tốt Cô ạ. Học rất vui ạ. | BC9: 17/7 Dạ. Em thấy được làm quen với tiếng Nhật business nhiều hơn ạ. Có những câu chưa từng nghe và sử dụng bao giờ ạ. | BF9: =datevalue(B9) -> 45572 | BG9: =MONTH(B9) -> 10 | BH9: 45572
A10: 420273234 | B10: 45607.421 | C10: ThuNH | D10: HV mới | E10: Nguyễn Thị Hạnh | F10: Nữ | G10: 8068456930 | H10: nguyenhanh150197@gmail.com | I10: Thường | J10: Full phí | K10: SKAI51030JP | L10: GV Nhật Bản | M10: Kaiwa 5 | N10: 30 | O10: Lớp 1-1 | P10: Mục tiêu học tập: muốn học nói chuyện trôi chảy hơn, làm trong ngành dịch vụ, giao tiếp nhiều LH line: 8068456930 Nguyễn Thị Hạnh ngày tháng năm sinh:15/01/1997 sdt:080-6845-6930 Địa chỉ email:nguyenhanh150197@gmail.co Lộ trình kaiwa 5 - NHKS GV Nhật: Thầy Matsuo lịch học: học tuần 2 buổi vào ngày học viên nghỉ - thống nhất giờ học vào ngày nghỉ với giáo viên - báo lại lịch học bắt đầu sau ngày 18/11 Ưu đãi: tặng khóa luyện thi JLPT N2 | Q10: 35445 | R10: làm tại cửa hàng | S10: Lớp 1-1 | T10: 18 | U10: 45619 | V10: Bảo lưu | W10: 45986 | X10: 09h30 | Y10: LKCD | Z10: 30 | AF10: matsuo | AH10: Nguyễn Thị Hạnh - kaiwa 5 ( 20/11/2024) - 001 | AJ10: 6 | AK10: Nguyễn Thị Hạnh | AL10: Mục tiêu học tập: muốn học nói chuyện trôi chảy hơn, làm trong ngành dịch vụ, giao tiếp nhiều | AO10: 24/11/2024 Dạ,sensei e thấy ổn ạ | AQ10: 8/03/2025 dạo này công việc bận rộn, em học thì vẫn ổn ạ, nhưng không có nhiều time học nhiều như trước thôi ạ | BF10: =datevalue(B10) -> 45607 | BG10: =MONTH(B10) -> 11 | BH10: 45599
A11: 420276012 | B11: 45700.369 | C11: DuyenLT | D11: HV mới | E11: Nguyễn Thị Thuỷ | F11: Nữ | G11: 123 | H11: tamthuyan1991@gmail.com | I11: Thường | J11: Full phí | K11: CKAI231030VN | L11: GV Việt Nam | M11: Kaiwa 2 | N11: 60.0096 | O11: Lớp 1-1 | P11: - Liên hệ line: https://drive.google.com/file/d/1Q6tFq2Mn1ErYO7jr7h_7MaV1a01WXUjq/view?usp=sharing - tặng jlpt video N4+ N3 - Lịch học: 246, giờ: 21h-21h30 (giờ nhật) - sn 92, học tiếp thu chậm sợ k nhớ được, yêu cầu SS nữ, vui tính nhiệt tình. Hỗ trợ học sớm | Q11: 33922 | R11: tts thực phẩm | S11: Lớp 1-1 | T11: 43.0096 | U11: 2025-02-26 2025-06-26 | V11: Bảo lưu | W11: 28/02/2025 2025-11-08 | X11: 19h30 | Y11: 57 | Z11: 30 | AF11: nunt/thaodtt | AH11: Nguyễn Thị Thuỷ - kaiwa 2 ( 14/02/2025) - 001 | AK11: Nguyễn Thị Thuỷ | AO11: 27/02/2025 chưa có chuẩn bị bài | AP11: 11/07/2025 15:28 ThuyTam E cũng hơi hơi quen oy ss😊 15:28 ThuyTam Trắc phải học hết khoá mới quen hoàn toàn ạ 15:28 ThuyTam 😊😊 | BF11: =datevalue(B11) -> 45700 | BG11: =MONTH(B11) -> 2 | BH11: 45699
A12: 420276401 | B12: 45710.371 | C12: LienQTM | D12: HV mới | E12: Lê Thị Kim Duyên | F12: Nữ | G12: 8095570808 | H12: ngocle080885@gmail.com | I12: Thường | J12: Full phí | K12: SKAI61030JP | L12: GV Nhật Bản | M12: Kaiwa 6 | N12: 120 | O12: Lớp 1-1 | P12: - Zalo: 8095570808 - Lớp kaiwa 6, lớp 1:1, giáo viên Nhật , full phí - Lịch học : bổ sung sau - Họ và tên, năm sinh: Lê Thị Kim Duyên,1985 - Email: ngocle080885@gmail.com - Tăng JLPT video N2 - Mục tiêu học: muốn học kaiwa cao cấp | Q12: 31100 | R12: Viza Vĩnh trú, làm tự do | S12: Lớp 1-1 | T12: 107 | U12: 45784 | V12: Bảo lưu | W12: 45931 | X12: 19h00 9h00(5) | Y12: 245 | Z12: 30 | AF12: joji | AH12: Lê Thị Kim Duyên - Kaiwa 6 - 001 Lê Thị Kim Duyên - kaiwa 3 ( 07/05/2025 ) - 001 | AK12: Lê Thị Kim Duyên | AL12: - Mục tiêu học: muốn học kaiwa phục vụ công việc | AO12: 08/05/2025 Dạ tốt lắm ạ E biết thêm được những điều bản thân mình thiếu sót Rất hay ất đúng với những gì e cần | AP12: 15/05/2025 Dạ quen Thích lắm ạ Thầy dạy hay E hiểu ạ | BF12: =datevalue(B12) -> 45710 | BG12: =MONTH(B12) -> 2 | BH12: 45711
A13: 420277322 | B13: 45740.462 | C13: TrangNL | D13: HV mới | E13: Vũ Thi Anh | F13: Nam | G13: 1 | H13: anhvu40006@gmail.com | I13: Thường | J13: Full phí | K13: SKAI41030JP | L13: GV Nhật Bản | M13: Kaiwa 4 | N13: 30 | O13: Lớp 1-1 | P13: """- Line: https://drive.google.com/drive/home - Tặng video JLPT N2 - Lịch học: 246, giờ: 20h00 Nhật - Khoá học: kaiwa 4 - Sắp xếp SS cứng và nhiệt tình, vui vẻ - Học để cải thiện kaiwa phục vụ trong công việc | Q13: 35051 | R13: Thực phẩm | S13: Lớp 1-1 | T13: 12 | U13: 45747 | V13: Bảo lưu | W13: 45847 | X13: 18h00 | Y13: 246 | Z13: 30 | AF13: Ueno/kojima | AH13: Vũ Thi Anh - kaiwa 4 ( 28/03/2025 ) - 001 | AK13: Vũ Thi Anh | AL13: - Mục tiêu học: học kaiwa để phục vụ công việc | AO13: 01/04/2025 Dạ k có vấn đề gì ạ | AQ13: 29/05/2025 11:03 アイン Dạ cô hướng dẫn e tốt lắm ạ 11:03 アイン E sai ở đâu là cô chỉnh cho e luôn ạ | BF13: =datevalue(B13) -> 45740 | BG13: =MONTH(B13) -> 3
A14: 420276218 | B14: 45729.751 | C14: DuyenLT | D14: HV mới | E14: Bùi Vi Lâm | F14: Nữ | H14: Vilambui1818@gmail.com | I14: Thường | J14: Full phí | K14: SKAI21030VN | L14: GV Việt Nam | M14: Kaiwa 2 | N14: 60 | O14: Lớp 1-1 | P14: - Liên hệ zalo: 0339713299 - Tặng video jlpt N3 - Lịch học: 22h-22h30 (giờ nhật) thứ 4,7 và CN - hv dhs sn 2006, đi làm quán kaiwa nhiều. | Q14: 38766 | R14: du học sinh | S14: Lớp 1-1 | T14: 0 | U14: 45735 | V14: Kết thúc | W14: 45978 | X14: 20h00 | Y14: 7CN | Z14: 30 | AF14: hangktt/thanhnn | AG14: GV350 | AI14: Bùi Vi Lâm - kaiwa 2 ( 19/03/2025 ) - 001 | AK14: Bùi Vi Lâm | AL14: - Mục tiêu học: muốn học kaiwa phục vụ công việc | AO14: 20/03/2025Dạ không ạaa , buổi đầu học nên chưa quen thôi ạ | AP14: 26/03/2025Dạ ss , em quen rồi ạaa BTVN: 3/3 | AQ14: 11/04/2025 Em đã kaiwa tự tin hơn bà vốn tìe vưngk cũng phong phú hơn r ạ | AR14: 25/04/2025 Dạ không ạ , em cảm ơn ss | AS14: 05/05/2025 Ss vẫn hướng dẫn e tốt ạ , em kaiwa cũng tốt hơn nhiều r ạ | AT14: 21/05/2025 dạ ổn ss ạ | AV14: 15/11/2025 So với các bạn sang Nhật cùng thời điểm thì em cảm thấy mình kaiwa có tự tin hơn ạ . Được khen khá nhiều ạ . | BF14: =datevalue(B14) -> 45729 | BG14: =MONTH(B14) -> 3
A15: =IFERROR(__xludf.DUMMYFUNCTION("Query(IMPORTRANGE(""https://docs.google.com/spreadsheets/d/1ICLXVn2a8EFOzyqDCHT97ZW5nSwRxTik3n5ruRV5Rg4/edit#gid=0"",""Tổng!A4502:Z10000""),""Select Col1,Col2,Col3,Col4,Col5,Col6,Col7,Col8,Col9,Col10,Col11,Col12,Col13,Col14,Col15,Col16,Col17,Col18 where C"&"ol19 = 'CVHT01'"")"),"#REF!") -> #REF! | S15: =IFERROR(__xludf.DUMMYFUNCTION("IMPORTRANGE(""https://docs.google.com/spreadsheets/d/1Yw0RASmlJCsUM9ySWss8BpZKd1mhFu3_lmRbXRXuJis/edit?gid=0#gid=0"",""3.Chấm buổi!H14:Y"")"),"#REF!") -> #REF! | AK15: Trần Văn Ta | AL15: Không liên lạc dk, đã cọc kaiwa 4 nhưng k phản hồi | AO15: 10/04/2025Dạ tốt ạ không có vần đề gì hết ạ Chỉ có điều thời gian hơi ít Nếu được 45 hay 60p thì tuyệt vời ạ | AP15: 18/04/2025 đã quen rồi ạ Dạ rất tốt ạ | AQ15: 09/05/2025 dạ e cảm thấy tiếng nhật của mình ổn hơn ạ | AS15: 12/06/2025 Dạ e đã vẫn dụng rồi ạ Hơi chưa quen miệng nhưng e cố gắn ạ | AV15: 24/07/2025 Dạ mong sensei chỉ e với ạ | AW15: 08/09/2025 @Phòng Đào Tạo Edura Gv Chuyên Môn dạ tốt ạ Hiện tại thì không có khó khăn gì ạ | AY15: 03/11/2025 Dạ nếu có gì không hiểu mong ss chỉ e với ạ Dạ cô ngọc chỉ e rất nhiệt tình ạ | BF15: =datevalue(B15) -> #VALUE! | BG15: =MONTH(B15) -> 12
AK16: Phạm Hồng Sơn | AL16: 04/6/2026 đã hỏi han | AO16: 15/04/2025 10:03 Son Vâng tốt ạ 10:03 Son Ko có vấn đề gì ạ | AP16: 22/04/2025 Quen rồi ạ Vâng ổn ạ 07:33 Son Diễm ss cũng nhiệt tình ạ 07:33 Son Nói chung tạm thời là ổn ạ | AQ16: 27/05/2025 Vâng có tốt hơn rồi ạ, Vâng , có tự tin hơn ạ | AS16: 13/06/2025 Vẫn tốt , ko có vấn đề gì ạ | AU16: 29/07/2025 17:48 Son Vâng 17:48 Son Không cần hỗ trợ gì đâu ạ | BF16: =datevalue(B16) -> #VALUE! | BG16: =MONTH(B16) -> 12
AK17: Nguyễn Thành Tây | AL17: bảo lưu nhắn tin lại k được nên kết thúc khóa | AO17: 17/04/2025dạ vâng ạ cảm ơn ss đã luôn hỗ trợ em nhiệt tình ạ...tại do cv mà em không trả lời tn của ss nhưng lúc nào cũng luôn quan tâm | AP17: 07/05/2025dần dần quen ạ dạ không ss ạ...ss linh nhiệt tình lắm ạ | AQ17: 21/05/2025 dạ vẫn bình thường và rất tốt ạ...chỉ là dạo này cv của em nó hơi nhiều một chút nên em cũng ít thời gian lại ạ | BF17: =datevalue(B17) -> #VALUE! | BG17: =MONTH(B17) -> 12
AK18: Hà Đức Quân | AL18: không thấy liên lạc | AO18: 17/04/2025 Dạ cô dạy vui lắm ạ, 11:15 ハ ドック クァン Đc ạ , cô cũng đang dạy trg tiếng 11:15 ハ ドック クァン Nên k có khó khăn gì | AP18: 22/04/2025 Dạ cũng hòm hòm r ạ | AQ18: 07/05/2025 dạ ss vẫn ổn ạ | AR18: 11/06/2025 Dạ ổn ạ | AT18: 16/07/2025 Dạ ổn ạ | AV18: 29/07/2025 đợi ph | BF18: =datevalue(B18) -> #VALUE! | BG18: =MONTH(B18) -> 12
AK19: Đỗ Văn Thiện | AO19: 12/04/2025 em học ổn ạ | AP19: 19/05/2025 Ko có vấn đề j ss ạ | BF19: =datevalue(B19) -> #VALUE! | BG19: =MONTH(B19) -> 12
AK20: Dương Thuý Vy | AL20: đợi ph 4/6 | AO20: 16/04/2025 Dạ không có vấn đề gì ạ. | AP20: 22/04/2025 Dạ em cũng quen rồi ạ Sensei cũng dạy tận tình nữa ạ | AQ20: 09/05/2025 Dạ em cảm thấy mình tự tin nói chuyện hơn trước một chút rồi ạ. Trong buổi học cùng cô giáo cũng rất là vui,cô cũng chỉ dậy giải thích từ chi tiết, và sửa lỗi phát âm cho em ạ | AR20: 22/05/2025 Dạ không có vấn đề gì ạ | AS20: 11/06/2025 dạ em cảm thấy khi em nói chuyện với đồng nghiệp nơi làm việc thì tự tin hơn trước với sử dụng được nhiều mẫu câu trong hội thoại để ứng dụng trong cuộc sống r ạ | AV20: 14/07/2025 Dạ cũng bình thường ạ Có cái bài về thể thao thì hơi khó thôi ạ | BF20: =datevalue(B20) -> #VALUE! | BG20: =MONTH(B20) -> 12
AK21: Võ Cẩm Nhung | AL21: quá hạn bảo lưu => kết thúc | AO21: 17/04/2025 Dạ ngày đầu nên em chưa theo kịp | AP21: 21/10/2025 18:01 ニュン Dạ ss mình học có nữa tiếng thôi hả ss . Cô giáo giỏi và xinh đó ss ơi 😆 18:02 ニュン Lâu rồi em k học nên em còn yếu nhiều mong ss nói cô giáo hổ trợ em nha | BF21: =datevalue(B21) -> #VALUE! | BG21: =MONTH(B21) -> 12
AK22: Trần Đức Biển | AL22: đợi ph 4/6 | AO22: 17/04/2025 vâng hôm nay học rất tốt ạ. Hiện tại đang ở mức bình thường nên chưa khó khăn, có thể hướng em kaiwa cao hơn 1 chút của N3, em đang tính chuyển công việc yêu cầu N3 nak. | AP22: 22/04/2025 Cũng quen rồi ss ạ. Tuy chưa thể ns đc nhiều | AQ22: 09/05/2025 vâng, học vừa tốt vừa vui ss ạ, nhưng thời gian học có 30p ko ns được nhiều lúc nào cũng trong tình trạng chảy cho kịp thời gian cả giáo viên lẫn trò | AR22: 22/05/2025 Hiện tại thì không vẫn đề gì ss | AS22: 05/06/2025 không vấn đề gì ss ạ, học vẫn cứ học thôi ss, học ổn đk tiếp | AT22: 11/06/2025 @Chika Sensei vâng, nếu có thể giúp em tốt hơn thì cũng đáng đầu tư dài thôi Ss. | AU22: 23/06/2025 nhắc test | AW22: 11/07/2025 dạ không Sense, cứ duy trì đều vậy thôi ạ, nay học ít nên có thời gian chuẩn bị tốt và đỡ mệt hơn | BF22: =datevalue(B22) -> #VALUE! | BG22: =MONTH(B22) -> 12
AK23: Nguyễn Thanh Xuân | AO23: 22/04/2025 Ko có gì ak | BF23: =datevalue(B23) -> #VALUE! | BG23: =MONTH(B23) -> 12
AK24: Lê Thị Kim Hoàng | AL24: không thấy liên hệ | AO24: 19/04/2025 Ok lắm ạ Chỉ có bài nghe e ko nghe được | AP24: 25/04/2025 Dạ . Ok ạ Một số từ vựng và ngữ pháp e học rồi nhưng ko kaiwa được. Cô giáo đang kèm e kaiw Nên thấy khá ok ạ | AQ24: 19/06/2025 Vâng ạ Có gì ko hiểu e sẽ hỏi Thảo 先生ạ | AS24: 18/07/2025 E tự tin hơn một chút rồi ạ Lúc trước nghe được nhưng ko nói lại được Nay nói được câu ngắn Và phản xạ nhanh hơn | BF24: =datevalue(B24) -> #VALUE! | BG24: =MONTH(B24) -> 12
AK25: Nguyễn Ngọc Dung | AL25: không thấy liên hệ (màu vàng) | AO25: 20/04/2025Dạ em cũng chưa biết nữa chị mới học 1 buổi a chi | AP25: 24/04/2025 Dạ cũng hơi quen mà thời gian ít quá nên em thấy học không có duoc nhiều | AQ25: 22/05/2025 Em cảm nhận em chua nói được suôn cau chị oi ( gửi thêm tài liệu nghe luyện) | AS25: 13/06/2025 Em cũng vậy a chi, học vẫn ổn a | BF25: =datevalue(B25) -> #VALUE! | BG25: =MONTH(B25) -> 12
AK26: Hoàng Thị Lý | AO26: 21/04/2025 dạ tốt ạ jo s gửi e ít bài e lm ạ | AP26: 05/05/2025 đã quen rồi a GV nhiệt tình | AQ26: Không gặp khó khăn gì a | BF26: =datevalue(B26) -> #VALUE! | BG26: =MONTH(B26) -> 12
AK27: Trần Văn Long | AO27: 21/04/2025 Dạ,tốt ss ơi | AP27: 05/05/2025 10:35 Trần Long Có ss ơi 10:36 Trần Long Ko vấn đề gì đâu ss ạ | AY27: 11/06/2026 @Phòng Đào Tạo Edura Gv Chuyên Môn dạ vẫn tốt ss | BF27: =datevalue(B27) -> #VALUE! | BG27: =MONTH(B27) -> 12
AK28: Trịnh Thị Kiều Trang | AO28: 25/04/2025 học ổn ạ | AP28: 16/05/2025 E cũng quen dần rồi nhưng e cungx chia sex thật là kết nối e kém và công việc của e khá bận nên e k tập trung dc nhiều lắm ạ! Nên e cũng đang có ý định học hết số buổi e đóng tiền thì nghỉ ss ah! Mong ss thông cảm ạ! | BF28: =datevalue(B28) -> #VALUE! | BG28: =MONTH(B28) -> 12
AK29: Phan Thị Thu Cúc | AO29: 21/04/2025 Dạ tốt ạ,nếu cần gì e sẽ nhắn ạ😊😊 Vâng,ss nhiệt tình ạ🥰🥰 | AP29: 26/04/2025 Dạ quen r ạ | AQ29: 16/05/2025 E Đã được ôn lại một vài kiến thức,củng học thêm vài từ vựng,có vẻ phần nghe ổn hơn trước một chút ạ | AR29: 30/05/2025 Vẫn tốt ạ | AS29: 05/06/2025 Vâng củng dần quen r ạ, gv hd tốt | AT29: 14/06/2025 E định học chắc từ vựng ngữ pháp đã ss ạ | AU29: 02/07/2025 nhắc nhờ test | AV29: 11/07/2025 dạ em học vẫn tốt a | BF29: =datevalue(B29) -> #VALUE! | BG29: =MONTH(B29) -> 12
AK30: Đặng Văn Lý | AL30: đợi ph 4/6 | AO30: 23/04/2025Dạ cũng ổn , mới học nên cũng hơi bỡ ngỡ ss ạ | AP30: 05/05/2025 Dạ em quen r ạ Em thấy phù hợp ạ | AQ30: 05/06/2025 Dạ tự tin giao tiếp hơn rồi ạ | AR30: 19/06/2025 Dạ tốt ạ | AT30: 29/07/2025 Dạ tốt ạ | AV30: 25/08/2025 đợiph | BF30: =datevalue(B30) -> #VALUE! | BG30: =MONTH(B30) -> 12
AK31: Trần Văn Giang | AO31: 16/05/2025 học ổn a | AP31: 21/05/2025 16:10 Giang Vâng 16:10 Giang Em thấy quen rồi ạ | AR31: 13/06/2025 18:43 Giang Em chào chị ạ 18:43 Giang Dạo này em học vẫn ổn chị ạ | BF31: =datevalue(B31) -> #VALUE! | BG31: =MONTH(B31) -> 12
AK32: Lê Thị Giang | AO32: 02/05/2025 dạ không có vấn đề gì ạ | AP32: 14/05/2025 dạ rồi ạ | AS32: 23/06/2025 dạ em tốt hơn nhiều rồi ạ | AT32: 10/07/2025 đợi ph | BF32: =datevalue(B32) -> #VALUE! | BG32: =MONTH(B32) -> 12
AK33: Nguyễn Đình Tuấn | AL33: đợi ph 4/6 | AO33: 10/05/2025 dạ tốt ạ mới buổi đầu tiên bài đang dễ nên em thấy tốc độ bth ạ | AP33: 14/05/2025Dạ cũng ok rồi ạ, cũng quen quen rồi ss ạ | AR33: 13/06/2025 học ổn a | AV33: 17/09/2025 đợi ph | BF33: =datevalue(B33) -> #VALUE! | BG33: =MONTH(B33) -> 12
AK34: Huỳnh Minh Châu | BF34: =datevalue(B34) -> #VALUE! | BG34: =MONTH(B34) -> 12
AK35: Huỳnh Văn Quyến | AO35: 10/05/2025 Dạa có ạa vấn đề anh thanh ạ khi ss bật đoạn băng cho em thì sau đó em hong còn nghe thấy ss nói gì nữa Phải thoát ra vào lại thì mới có thể nghe lại bình thường ạ Còn vấn để học thì ổn ạa | AP35: 24/05/2025Dạa em đã quen rồi ss ạa, Dạa có ss ạa | AU35: 15/11/2025 đợi ph | BF35: =datevalue(B35) -> #VALUE! | BG35: =MONTH(B35) -> 12
AK36: Nguyễn Văn Hồng | AO36: 29/04/2025 Dạ ổn ạ | AP36: 09/05/2025 Dạ rồi ạ | AQ36: 22/10/2025Dạ quen rồi ạ.mà từ vựng ít ỏi với quên ngữ pháp nên nc bập bẹ ạ(pleading Moon) | AS36: 11/12/2025 đợi ph | BF36: =datevalue(B36) -> #VALUE! | BG36: =MONTH(B36) -> 12
AK37: Leo Trúc Mai | AO37: 14/05/2025 Dạ ổn ss ơi | AQ37: 19/06/2025 em học vẫn ổn ạ | BF37: =datevalue(B37) -> #VALUE! | BG37: =MONTH(B37) -> 12
AK38: Lý Thị Châm | AL38: out nhóm zl | AO38: 09/05/2025 Ui.lần đầu tiên học nên hồi hộp quá Quên luôn các mẫu câu cbi sẵn ở nhà 🥲🥲🥲 K nhớ ra đc gì cả ss ạ | AP38: 19/05/2025 ổn ạ | BF38: =datevalue(B38) -> #VALUE! | BG38: =MONTH(B38) -> 12
AK39: Nguyễn Trần Thị Mỹ Duyên | AL39: k liên lạc được nên kết thúc | AO39: 03/05/2025 Dạ tốt lắm ạ | AP39: 16/05/2025 Dạ e cũng đã quen rồi ạ Dạ Sinh ss hướng dẫn e tốt lắm ạ | AQ39: 19/06/2025 Dạ e thấy tiếng Nhật cũng khá lên nhiều ạ Vâng ạ Sinh ss vẫn đang hướng dẫn e tốt ạ | BF39: =datevalue(B39) -> #VALUE! | BG39: =MONTH(B39) -> 12
AK40: Phùng Thị Phượng | AO40: 10/05/2025 dạ tạm thời không có vấn đề gì ạ | AP40: 19/05/2025 vâng, e bắt đầu quen dần r ạ | AS40: 23/06/2025 e thấy đã ổn hơn chút r ạ, nhưng chưa thể nói là tốt đc ạ😅 | AV40: 31/07/2025 vào buổi kiểm tra hôm trc thì e thấy các ngữ pháp sensei hỏi thì e đều nhớ ạ, nhưng phần kính ngữ và thực hành tình huống thì e cảm thấy mình vẫn chưa làm tốt lắm | BF40: =datevalue(B40) -> #VALUE! | BG40: =MONTH(B40) -> 12
...

Sheet 3.Chấm buổi
J1: =today() -> 46283 | Y1: 2026 | AC1: Tháng 1 | BN1: Tháng 2 | CV1: Tháng 3 | EG1: 45748 | FQ1: 46143 | HB1: 46174 | IL1: 46204 | JW1: 46235 | LH1: 46266 | MR1: 46296 | OC1: 46327 | PM1: 46357
A2: ID | B2: Họ tên HV | C2: Gói học | D2: Nội dung khoá | E2: Tổng số buổi | F2: Khoá học | G2: Email | H2: Mô hình | I2: Số buổi còn lại | J2: Ngày bắt đầu học | K2: Trạng thái | L2: Ngày kết thúc/Bảo lưu | M2: Giờ học (1) | N2: Lịch học (1) | O2: Thời lượng buổi học (1) | P2: Giờ học (2) | Q2: Lịch học (2) | R2: Thời lượng buổi học (2) | S2: Vòng lặp | T2: Ngày học | U2: Giáo viên | V2: Mã GV | W2: Tên lớp | X2: Tổng số buổi đã học | Y2: Tổng số buổi đã học | Z2: Tổng số buổi HV nghỉ có phép | AA2: Tổng số buổi HV nghỉ không phép | AB2: Tổng số buổi GV nghỉ | AC2: Số buổi đã học | AD2: Số buổi xin nghỉ có phép A | AE2: Số buổi bảo lưu B | AF2: Số buổi nghỉ sai quy định C | AG2: Số buổi GV xin nghỉ D | AH2: Số buổi lỗi kĩ thuật E | AI2: 46023 | AJ2: 46024 | AK2: 46025 | AL2: 46026 | AM2: 46027 | AN2: 46028 | AO2: 46029 | AP2: 46030 | AQ2: 46031 | AR2: 46032 | AS2: 46033 | AT2: 46034 | AU2: 46035 | AV2: 46036 | AW2: 46037 | AX2: 46038 | AY2: 46039 | AZ2: 46040 | BA2: 46041 | BB2: 46042 | BC2: 46043 | BD2: 46044 | BE2: 46045 | BF2: 46046 | BG2: 46047 | BH2: 46048 | BI2: 46049 | BJ2: 46050 | BK2: 46051 | BL2: 46052 | BM2: 46053 | BN2: Số buổi đã học | BO2: Số buổi xin nghỉ có phép A | BP2: Số buổi bảo lưu B | BQ2: Số buổi nghỉ sai quy định C | BR2: Số buổi GV xin nghỉ D | BS2: Số buổi lỗi kĩ thuật E | BT2: 46054 | BU2: 46055 | BV2: 46056 | BW2: 46057 | BX2: 46058 | BY2: 46059 | BZ2: 46060 | CA2: 46061 | CB2: 46062 | CC2: 46063 | CD2: 46064 | CE2: 46065 | CF2: 46066 | CG2: 46067 | CH2: 46068 | CI2: 46069 | CJ2: 46070 | CK2: 46071 | CL2: 46072 | CM2: 46073 | CN2: 46074 | CO2: 46075 | CP2: 46076 | CQ2: 46077 | CR2: 46078 | CS2: 46079 | CT2: 46080 | CU2: 46081 | CV2: Số buổi đã học | CW2: Số buổi xin nghỉ có phép A | CX2: Số buổi bảo lưu B | CY2: Số buổi nghỉ sai quy định C | CZ2: Số buổi GV xin nghỉ D | DA2: Số buổi lỗi kĩ thuật E | DB2: 46082 | DC2: 46083 | DD2: 46084 | DE2: 46085 | DF2: 46086 | DG2: 46087 | DH2: 46088 | DI2: 46089 | DJ2: 46090 | DK2: 46091 | DL2: 46092 | DM2: 46093 | DN2: 46094 | DO2: 46095 | DP2: 46096 | DQ2: 46097 | DR2: 46098 | DS2: 46099 | DT2: 46100 | DU2: 46101 | DV2: 46102 | DW2: 46103 | DX2: 46104 | DY2: 46105 | DZ2: 46106 | EA2: 46107 | EB2: 46108 | EC2: 46109 | ED2: 46110 | EE2: 46111 | EF2: 46112 | EG2: Số buổi đã học | EH2: Số buổi xin nghỉ có phép A | EI2: Số buổi bảo lưu B | EJ2: Số buổi nghỉ sai quy định C | EK2: Số buổi GV xin nghỉ D | EL2: Số buổi lỗi kĩ thuật E | EM2: 46113 | EN2: 46114 | EO2: 46115 | EP2: 46116 | EQ2: 46117 | ER2: 46118 | ES2: 46119 | ET2: 46120 | EU2: 46121 | EV2: 46122 | EW2: 46123 | EX2: 46124 | EY2: 46125 | EZ2: 46126 | FA2: 46127 | FB2: 46128 | FC2: 46129 | FD2: 46130 | FE2: 46131 | FF2: 46132 | FG2: 46133 | FH2: 46134 | FI2: 46135 | FJ2: 46136 | FK2: 46137 | FL2: 46138 | FM2: 46139 | FN2: 46140 | FO2: 46141 | FP2: 46142 | FQ2: Số buổi đã học | FR2: Số buổi xin nghỉ có phép A | FS2: Số buổi bảo lưu B | FT2: Số buổi nghỉ sai quy định C | FU2: Số buổi GV xin nghỉ D | FV2: Số buổi lỗi kĩ thuật E | FW2: 46143 | FX2: 46144 | FY2: 46145 | FZ2: 46146 | GA2: 46147 | GB2: 46148 | GC2: 46149 | GD2: 46150 | GE2: 46151 | GF2: 46152 | GG2: 46153 | GH2: 46154 | GI2: 46155 | GJ2: 46156 | GK2: 46157 | GL2: 46158 | GM2: 46159 | GN2: 46160 | GO2: 46161 | GP2: 46162 | GQ2: 46163 | GR2: 46164 | GS2: 46165 | GT2: 46166 | GU2: 46167 | GV2: 46168 | GW2: 46169 | GX2: 46170 | GY2: 46171 | GZ2: 46172 | HA2: 46173 | HB2: Số buổi đã học | HC2: Số buổi xin nghỉ có phép A | HD2: Số buổi bảo lưu B | HE2: Số buổi nghỉ sai quy định C | HF2: Số buổi GV xin nghỉ D | HG2: Số buổi lỗi kĩ thuật E | HH2: 46174 | HI2: 46175 | HJ2: 46176 | HK2: 46177 | HL2: 46178 | HM2: 46179 | HN2: 46180 | HO2: 46181 | HP2: 46182 | HQ2: 46183 | HR2: 46184 | HS2: 46185 | HT2: 46186 | HU2: 46187 | HV2: 46188 | HW2: 46189 | HX2: 46190 | HY2: 46191 | HZ2: 46192 | IA2: 46193 | IB2: 46194 | IC2: 46195 | ID2: 46196 | IE2: 46197 | IF2: 46198 | IG2: 46199 | IH2: 46200 | II2: 46201 | IJ2: 46202 | IK2: 46203 | IL2: Số buổi đã học | IM2: Số buổi xin nghỉ có phép A | IN2: Số buổi bảo lưu B | IO2: Số buổi nghỉ sai quy định C | IP2: Số buổi GV xin nghỉ D | IQ2: Số buổi lỗi kĩ thuật E | IR2: 46204 | IS2: 46205 | IT2: 46206 | IU2: 46207 | IV2: 46208 | IW2: 46209 | IX2: 46210 | IY2: 46211 | IZ2: 46212 | JA2: 46213 | JB2: 46214 | JC2: 46215 | JD2: 46216 | JE2: 46217 | JF2: 46218 | JG2: 46219 | JH2: 46220 | JI2: 46221 | JJ2: 46222 | JK2: 46223 | JL2: 46224 | JM2: 46225 | JN2: 46226 | JO2: 46227 | JP2: 46228 | JQ2: 46229 | JR2: 46230 | JS2: 46231 | JT2: 46232 | JU2: 46233 | JV2: 46234 | JW2: Số buổi đã học | JX2: Số buổi xin nghỉ có phép A | JY2: Số buổi bảo lưu B | JZ2: Số buổi nghỉ sai quy định C | KA2: Số buổi GV xin nghỉ D | KB2: Số buổi lỗi kĩ thuật E | KC2: 46235 | KD2: 46236 | KE2: 46237 | KF2: 46238 | KG2: 46239 | KH2: 46240 | KI2: 46241 | KJ2: 46242 | KK2: 46243 | KL2: 46244 | KM2: 46245 | KN2: 46246 | KO2: 46247 | KP2: 46248 | KQ2: 46249 | KR2: 46250 | KS2: 46251 | KT2: 46252 | KU2: 46253 | KV2: 46254 | KW2: 46255 | KX2: 46256 | KY2: 46257 | KZ2: 46258 | LA2: 46259 | LB2: 46260 | LC2: 46261 | LD2: 46262 | LE2: 46263 | LF2: 46264 | LG2: 46265 | LH2: Số buổi đã học | LI2: Số buổi xin nghỉ có phép A | LJ2: Số buổi bảo lưu B | LK2: Số buổi nghỉ sai quy định C | LL2: Số buổi GV xin nghỉ D | LM2: Số buổi lỗi kĩ thuật E | LN2: 46266 | LO2: =LN2+1 -> 46267 | LP2: =LO2+1 -> 46268 | LQ2: =LP2+1 -> 46269 | LR2: =LQ2+1 -> 46270 | LS2: =LR2+1 -> 46271 | LT2: =LS2+1 -> 46272 | LU2: =LT2+1 -> 46273 | LV2: =LU2+1 -> 46274 | ... MQ2: =MP2+1 -> 46295 | MR2: Số buổi đã học | MS2: Số buổi xin nghỉ có phép A | MT2: Số buổi bảo lưu B | MU2: Số buổi nghỉ sai quy định C | MV2: Số buổi GV xin nghỉ D | MW2: Số buổi lỗi kĩ thuật E | MX2: 46296 | MY2: =MX2+1 -> 46297 | MZ2: =MY2+1 -> 46298 | NA2: =MZ2+1 -> 46299 | NB2: =NA2+1 -> 46300 | NC2: =NB2+1 -> 46301 | ND2: =NC2+1 -> 46302 | NE2: =ND2+1 -> 46303 | NF2: =NE2+1 -> 46304 | ... OB2: =OA2+1 -> 46326 | OC2: Số buổi đã học | OD2: Số buổi xin nghỉ có phép A | OE2: Số buổi bảo lưu B | OF2: Số buổi nghỉ sai quy định C | OG2: Số buổi GV xin nghỉ D | OH2: Số buổi lỗi kĩ thuật E | OI2: 46327 | OJ2: =OI2+1 -> 46328 | OK2: =OJ2+1 -> 46329 | OL2: =OK2+1 -> 46330 | OM2: =OL2+1 -> 46331 | ON2: =OM2+1 -> 46332 | OO2: =ON2+1 -> 46333 | OP2: =OO2+1 -> 46334 | OQ2: =OP2+1 -> 46335 | ... PL2: =PK2+1 -> 46356 | PM2: Số buổi đã học | PN2: Số buổi xin nghỉ có phép A | PO2: Số buổi bảo lưu B | PP2: Số buổi nghỉ sai quy định C | PQ2: Số buổi GV xin nghỉ D | PR2: Số buổi lỗi kĩ thuật E | PS2: 46357 | PT2: =PS2+1 -> 46358 | PU2: =PT2+1 -> 46359 | PV2: =PU2+1 -> 46360 | PW2: =PV2+1 -> 46361 | PX2: =PW2+1 -> 46362 | PY2: =PX2+1 -> 46363 | PZ2: =PY2+1 -> 46364 | QA2: =PZ2+1 -> 46365 | ... QV2: =QU2+1 -> 46386 | QW2: 46387 | QX2: Ngày tạo tài khoản
A3: =IFERROR(__xludf.DUMMYFUNCTION("QUERY('1.Chăm sóc'!A4:AG14,""Select A,E,K,I,N,L,H,O"")"),4.20274574E8) -> 420274574 | B3: =IFERROR(__xludf.DUMMYFUNCTION("""COMPUTED_VALUE"""),"Đặng Văn Thạch") -> Đặng Văn Thạch | C3: =IFERROR(__xludf.DUMMYFUNCTION("""COMPUTED_VALUE"""),"SKAI231030VN") -> SKAI231030VN | D3: =IFERROR(__xludf.DUMMYFUNCTION("""COMPUTED_VALUE"""),"Thường") -> Thường | E3: =IFERROR(__xludf.DUMMYFUNCTION("""COMPUTED_VALUE"""),49.0) -> 49 | F3: =IFERROR(__xludf.DUMMYFUNCTION("""COMPUTED_VALUE"""),"GV Việt Nam") -> GV Việt Nam | G3: =IFERROR(__xludf.DUMMYFUNCTION("""COMPUTED_VALUE"""),"thachcd111cg2@gmail.com") -> thachcd111cg2@gmail.com | H3: =IFERROR(__xludf.DUMMYFUNCTION("""COMPUTED_VALUE"""),"Lớp 1-1") -> Lớp 1-1 | I3: =E3-Y3 -> 14 | J3: 45698 | K3: Bảo lưu | L3: 45736 | M3: 20h00 | N3: 246 | O3: 30 | U3: kojima/thaodtt | V3: GV33 | X3: 35 | Y3: =SUMIF($AC$2:QX$2,"Số buổi đã học",$AC3:QX3)+X3 -> 35 | Z3: =SUMIF($AC$2:QX$2,"Số buổi xin nghỉ có phép A",$AC3:QX3) -> 0 | AA3: =SUMIF($AC$2:QX$2,"Số buổi nghỉ sai quy định C",$AC3:QX3) -> 0 | AB3: =SUMIF($AC$2:QX$2,"Số buổi GV xin nghỉ D",$AC3:QX3) -> 0 | AC3: 0 | AD3: 0 | AE3: 0 | AF3: 0 | AG3: 0 | AH3: 0 | BN3: 0 | BO3: 0 | BP3: 0 | BQ3: 0 | BR3: 0 | BS3: 0 | CV3: 0 | CW3: 0 | CX3: 0 | CY3: 0 | CZ3: 0 | DA3: 0 | EG3: 0 | EH3: 0 | EI3: 0 | EJ3: 0 | EK3: 0 | EL3: 0 | FQ3: 0 | FR3: 0 | FS3: 0 | FT3: 0 | FU3: 0 | FV3: 0 | HB3: 0 | HC3: 0 | HD3: 0 | HE3: 0 | HF3: 0 | HG3: 0 | IL3: 0 | IM3: 0 | IN3: 0 | IO3: 0 | IP3: 0 | IQ3: 0 | JW3: 0 | JX3: 0 | JY3: 0 | JZ3: 0 | KA3: 0 | KB3: 0 | LH3: =Sum(LN3:MQ3)+LK3 -> 0 | LI3: =countif(LN3:MQ3,"A") -> 0 | LJ3: =countif(LN3:MRQ3,"B") -> 0 | LK3: =countif(LN3:MQ3,"C") -> 0 | LL3: =countif(LN3:MQ3,"D") -> 0 | LM3: =countif(LN3:MQ3,"E") -> 0 | QX3: 45750
A4: =IFERROR(__xludf.DUMMYFUNCTION("""COMPUTED_VALUE"""),4.20266164E8) -> 420266164 | B4: =IFERROR(__xludf.DUMMYFUNCTION("""COMPUTED_VALUE"""),"Phan Ngọc Khánh Linh") -> Phan Ngọc Khánh Linh | C4: =IFERROR(__xludf.DUMMYFUNCTION("""COMPUTED_VALUE"""),"SKAI11030VN") -> SKAI11030VN | D4: =IFERROR(__xludf.DUMMYFUNCTION("""COMPUTED_VALUE"""),"Thường") -> Thường | E4: =IFERROR(__xludf.DUMMYFUNCTION("""COMPUTED_VALUE"""),90.0) -> 90 | F4: =IFERROR(__xludf.DUMMYFUNCTION("""COMPUTED_VALUE"""),"GV Việt Nam") -> GV Việt Nam | G4: =IFERROR(__xludf.DUMMYFUNCTION("""COMPUTED_VALUE"""),"10.phanngockhanhlinh11a2@gmail.com") -> 10.phanngockhanhlinh11a2@gmail.com | H4: =IFERROR(__xludf.DUMMYFUNCTION("""COMPUTED_VALUE"""),"Lớp 1-1") -> Lớp 1-1 | I4: =E4-Y4 -> -1 | J4: 45735 | K4: Kết thúc | L4: 45859 | M4: 20h00 | N4: 246 | O4: 30 | U4: canhnt/quyentn/diempvk | V4: GV426 | X4: 83 | Y4: =SUMIF($AC$2:QX$2,"Số buổi đã học",$AC4:QX4)+X4 -> 91 | Z4: =SUMIF($AC$2:QX$2,"Số buổi xin nghỉ có phép A",$AC4:QX4) -> 0 | AA4: =SUMIF($AC$2:QX$2,"Số buổi nghỉ sai quy định C",$AC4:QX4) -> 0 | AB4: =SUMIF($AC$2:QX$2,"Số buổi GV xin nghỉ D",$AC4:QX4) -> 0 | AC4: 8 | AD4: 0 | AE4: 0 | AF4: 0 | AG4: 0 | AH4: 0 | AM4: 2 | AN4: 0 | AR4: 1 | AY4: 2 | BG4: 2 | BI4: 0 | BM4: 1 | BN4: 0 | BO4: 0 | BP4: 0 | BQ4: 0 | BR4: 0 | BS4: 0 | CV4: 0 | CW4: 0 | CX4: 0 | CY4: 0 | CZ4: 0 | DA4: 0 | EG4: 0 | EH4: 0 | EI4: 0 | EJ4: 0 | EK4: 0 | EL4: 0 | FQ4: 0 | FR4: 0 | FS4: 0 | FT4: 0 | FU4: 0 | FV4: 0 | HB4: 0 | HC4: 0 | HD4: 0 | HE4: 0 | HF4: 0 | HG4: 0 | IL4: 0 | IM4: 0 | IN4: 0 | IO4: 0 | IP4: 0 | IQ4: 0 | JW4: 0 | JX4: 0 | JY4: 0 | JZ4: 0 | KA4: 0 | KB4: 0 | LH4: =Sum(LN4:MQ4)+LK4 -> 0 | LI4: =countif(LN4:MQ4,"A") -> 0 | LJ4: =countif(LN4:MRQ4,"B") -> 0 | LK4: =countif(LN4:MQ4,"C") -> 0 | LL4: =countif(LN4:MQ4,"D") -> 0 | LM4: =countif(LN4:MQ4,"E") -> 0 | QX4: 45751
A5: =IFERROR(__xludf.DUMMYFUNCTION("""COMPUTED_VALUE"""),1.0052874E7) -> 10052874 | B5: =IFERROR(__xludf.DUMMYFUNCTION("""COMPUTED_VALUE"""),"Phạm Thị Thương") -> Phạm Thị Thương | C5: =IFERROR(__xludf.DUMMYFUNCTION("""COMPUTED_VALUE"""),"CKAI121030VN") -> CKAI121030VN | D5: =IFERROR(__xludf.DUMMYFUNCTION("""COMPUTED_VALUE"""),"Thường") -> Thường | E5: =IFERROR(__xludf.DUMMYFUNCTION("""COMPUTED_VALUE"""),60.0) -> 60 | F5: =IFERROR(__xludf.DUMMYFUNCTION("""COMPUTED_VALUE"""),"GV Việt Nam") -> GV Việt Nam | G5: =IFERROR(__xludf.DUMMYFUNCTION("""COMPUTED_VALUE"""),"phamthithuongnb93@gmail.com") -> phamthithuongnb93@gmail.com | H5: =IFERROR(__xludf.DUMMYFUNCTION("""COMPUTED_VALUE"""),"Lớp 1-1") -> Lớp 1-1 | I5: =E5-Y5 -> 0 | J5: 2025-03-24 2026-05-08 | K5: Kết thúc | L5: 46210 | M5: 17h10 | N5: 357 | O5: 30 | U5: /quyentn/diempvk | V5: GV396 | X5: 40 | Y5: =SUMIF($AC$2:QX$2,"Số buổi đã học",$AC5:QX5)+X5 -> 60 | Z5: =SUMIF($AC$2:QX$2,"Số buổi xin nghỉ có phép A",$AC5:QX5) -> 0 | AA5: =SUMIF($AC$2:QX$2,"Số buổi nghỉ sai quy định C",$AC5:QX5) -> 0 | AB5: =SUMIF($AC$2:QX$2,"Số buổi GV xin nghỉ D",$AC5:QX5) -> 0 | AC5: 8 | AD5: 0 | AE5: 0 | AF5: 0 | AG5: 0 | AH5: 0 | AI5: 0 | AK5: 1 | AL5: 0 | AM5: 0 | AN5: 1 | AO5: 0 | AP5: 1 | AQ5: 0 | AV5: 0 | AW5: 1 | AX5: 0 | AY5: 1 | BD5: 1 | BE5: 0 | BF5: 1 | BG5: 0 | BH5: 0 | BJ5: 0 | BK5: 1 | BL5: 0 | BN5: 1 | BO5: 0 | BP5: 0 | BQ5: 0 | BR5: 0 | BS5: 0 | BV5: 1 | CV5: 0 | CW5: 0 | CX5: 0 | CY5: 0 | CZ5: 0 | DA5: 0 | EG5: 0 | EH5: 0 | EI5: 0 | EJ5: 0 | EK5: 0 | EL5: 0 | FQ5: 6 | FR5: 0 | FS5: 0 | FT5: 0 | FU5: 0 | FV5: 0 | GC5: 1 | GI5: 1 | GJ5: 1 | GQ5: 1 | GW5: 1 | GX5: 1 | HB5: 4 | HC5: 0 | HD5: 0 | HE5: 0 | HF5: 0 | HG5: 0 | HK5: 1 | HX5: 1 | HY5: 1 | IF5: 1 | IL5: 1 | IM5: 0 | IN5: 0 | IO5: 0 | IP5: 0 | IQ5: 0 | IR5: 1 | JW5: 0 | JX5: 0 | JY5: 0 | JZ5: 0 | KA5: 0 | KB5: 0 | LH5: =Sum(LN5:MQ5)+LK5 -> 0 | LI5: =countif(LN5:MQ5,"A") -> 0 | LJ5: =countif(LN5:MRQ5,"B") -> 0 | LK5: =countif(LN5:MQ5,"C") -> 0 | LL5: =countif(LN5:MQ5,"D") -> 0 | LM5: =countif(LN5:MQ5,"E") -> 0 | QX5: 45751
A6: =IFERROR(__xludf.DUMMYFUNCTION("""COMPUTED_VALUE"""),4.20277244E8) -> 420277244 | B6: =IFERROR(__xludf.DUMMYFUNCTION("""COMPUTED_VALUE"""),"Trần Tế Hanh") -> Trần Tế Hanh | C6: =IFERROR(__xludf.DUMMYFUNCTION("""COMPUTED_VALUE"""),"CKAI231030VN") -> CKAI231030VN | D6: =IFERROR(__xludf.DUMMYFUNCTION("""COMPUTED_VALUE"""),"Thường") -> Thường | E6: =IFERROR(__xludf.DUMMYFUNCTION("""COMPUTED_VALUE"""),105.0) -> 105 | F6: =IFERROR(__xludf.DUMMYFUNCTION("""COMPUTED_VALUE"""),"GV Việt Nam") -> GV Việt Nam | G6: =IFERROR(__xludf.DUMMYFUNCTION("""COMPUTED_VALUE"""),"has2107@gmail.com") -> has2107@gmail.com | H6: =IFERROR(__xludf.DUMMYFUNCTION("""COMPUTED_VALUE"""),"Lớp 1-1") -> Lớp 1-1 | I6: =E6-Y6 -> 0 | K6: Đang học | M6: 17h10 | N6: 246 | O6: 30 | P6: 30 | U6: huylt | V6: GV265 | X6: 73 | Y6: =SUMIF($AC$2:QX$2,"Số buổi đã học",$AC6:QX6)+X6 -> 105 | Z6: =SUMIF($AC$2:QX$2,"Số buổi xin nghỉ có phép A",$AC6:QX6) -> 0 | AA6: =SUMIF($AC$2:QX$2,"Số buổi nghỉ sai quy định C",$AC6:QX6) -> 0 | AB6: =SUMIF($AC$2:QX$2,"Số buổi GV xin nghỉ D",$AC6:QX6) -> 0 | AC6: 4 | AD6: 0 | AE6: 0 | AF6: 0 | AG6: 0 | AH6: 0 | AO6: 1 | BB6: 1 | BH6: 1 | BL6: 1 | BM6: 0 | BN6: 2 | BO6: 0 | BP6: 0 | BQ6: 0 | BR6: 0 | BS6: 0 | CB6: 1 | CT6: 1 | CU6: 0 | CV6: 7 | CW6: 0 | CX6: 0 | CY6: 0 | CZ6: 0 | DA6: 0 | DB6: 0 | DC6: 1 | DD6: 0 | DF6: 0 | DG6: 1 | DN6: 1 | DS6: 1 | DX6: 1 | EB6: 1 | EC6: 0 | ED6: 0 | EE6: 1 | EF6: 0 | EG6: 3 | EH6: 0 | EI6: 0 | EJ6: 0 | EK6: 0 | EL6: 0 | ET6: 1 | EU6: 0 | EW6: 0 | EX6: 0 | EY6: 1 | EZ6: 0 | FA6: 1 | FQ6: 7 | FR6: 0 | FS6: 0 | FT6: 0 | FU6: 0 | FV6: 0 | FZ6: 1 | GB6: 1 | GD6: 1 | GG6: 1 | GN6: 1 | GQ6: 1 | GS6: 0 | GT6: 0 | GU6: 1 | HB6: 5 | HC6: 0 | HD6: 0 | HE6: 0 | HF6: 0 | HG6: 0 | HI6: 0 | HJ6: 1 | HK6: 0 | HL6: 1 | HM6: 0 | HN6: 0 | HO6: 0 | HP6: 0 | HQ6: 1 | HZ6: 1 | ID6: 0 | IE6: 1 | IL6: 4 | IM6: 0 | IN6: 0 | IO6: 0 | IP6: 0 | IQ6: 0 | IT6: 1 | JA6: 1 | JF6: 1 | JG6: 0 | JI6: 0 | JJ6: 0 | JL6: 0 | JM6: 1 | JN6: 0 | JP6: 0 | JQ6: 0 | JS6: 0 | JU6: 0 | JW6: 0 | JX6: 0 | JY6: 0 | JZ6: 0 | KA6: 0 | KB6: 0 | LH6: =Sum(LN6:MQ6)+LK6 -> 0 | LI6: =countif(LN6:MQ6,"A") -> 0 | LJ6: =countif(LN6:MRQ6,"B") -> 0 | LK6: =countif(LN6:MQ6,"C") -> 0 | LL6: =countif(LN6:MQ6,"D") -> 0 | LM6: =countif(LN6:MQ6,"E") -> 0 | QX6: 45755
